Workbook

Sheet Overview
A2: 온라인 강의 요약 서비스 · 24개월 사업모델
A4: 노란 셀을 바꾸면 월별 전망과 아래 차트가 함께 갱신됩니다. 숫자는 실측 매출이 아닌 계획 시나리오입니다.
A6: 지표 | B6: M6 | C6: M12 | D6: M24
A7: 월 신규 가입 | B7: ='Monthly Model'!H14 -> 25.525694 | C7: ='Monthly Model'!N14 -> 34.206787 | D7: ='Monthly Model'!Z14 -> 61.430475
A8: 기말 유료 고객 | B8: ='Monthly Model'!H34 -> 18.102847 | C8: ='Monthly Model'!N34 -> 34.59717 | D8: ='Monthly Model'!Z34 -> 76.121595
A9: 월 순매출 (VAT 제외) | B9: ='Monthly Model'!H52 -> 318444.85 | C9: ='Monthly Model'!N52 -> 608595.68 | D9: ='Monthly Model'!Z52 -> 1339048.1
A10: 월 전체 비용 | B10: ='Monthly Model'!H74 -> 291812.85 | C10: ='Monthly Model'!N74 -> 313413.36 | D10: ='Monthly Model'!Z74 -> 368877.22
A11: 월 순이익 | B11: ='Monthly Model'!H80 -> 26632.002 | C11: ='Monthly Model'!N80 -> 276780.62 | D11: ='Monthly Model'!Z80 -> 873153.76
A12: 누적 순이익 | B12: ='Monthly Model'!H81 -> -905109.79 | C12: ='Monthly Model'!N81 -> 165615.33 | D12: ='Monthly Model'!Z81 -> 6966935
A13: 추천 신규 가입 | B13: ='Monthly Model'!H11 -> 6.2731791e-05 | C13: ='Monthly Model'!N11 -> 2.2037555e-11 | D13: ='Monthly Model'!Z11 -> 2.7196614e-24
A16: 기간 합계 | B16: 1~12개월 | C16: 13~24개월 | D16: 24개월 합계
A17: 신규 가입 | B17: =SUM('Monthly Model'!C14:N14) -> 334.71808 | C17: =SUM('Monthly Model'!O14:Z14) -> 571.69745 | D17: =B17+C17 -> 906.41552
A18: 순매출 | B18: =SUM('Monthly Model'!C52:N52) -> 4033156 | C18: =SUM('Monthly Model'!O52:Z52) -> 11765075 | D18: =B18+C18 -> 15798231
A19: 전체 비용 | B19: =SUM('Monthly Model'!C74:N74) -> 3849139 | C19: =SUM('Monthly Model'!O74:Z74) -> 4208053.6 | D19: =B19+C19 -> 8057192.6
A20: 순이익 | B20: =SUM('Monthly Model'!C80:N80) -> 165615.33 | C20: =SUM('Monthly Model'!O80:Z80) -> 6801319.6 | D20: =B20+C20 -> 6966935
A21: 추천 가입 | B21: =SUM('Monthly Model'!C11:N11) -> 1.3755459 | C21: =SUM('Monthly Model'!O11:Z11) -> 2.0209111e-12 | D21: =B21+C21 -> 1.3755459
A22: 추천 무료월 획득 | B22: =SUM('Monthly Model'!C43:N43) -> 0.10110262 | C22: =SUM('Monthly Model'!O43:Z43) -> 1.4853697e-13 | D22: =B22+C22 -> 0.10110262
A23: 월별 매출 · 비용 · 순이익 (원) | F23: 모델 적용 규칙
A24: 월 | B24: 순매출 | C24: 전체 비용 | D24: 순이익
A25: M1 | B25: ='Monthly Model'!C52 -> 0 | C25: ='Monthly Model'!C74 -> 600811.72 | D25: ='Monthly Model'!C80 -> -600811.72 | F25: 사전예약 첫달 무료와 일반 14일 체험은 중복하지 않습니다.
A26: M2 | B26: ='Monthly Model'!D52 -> 126654.55 | C26: ='Monthly Model'!D74 -> 276941.03 | D26: ='Monthly Model'!D80 -> -150286.49 | F26: 카드 등록 고객의 무료 기간 종료 후, 다음 달 유료 전환을 근사합니다.
A27: M3 | B27: ='Monthly Model'!E52 -> 176698.45 | C27: ='Monthly Model'!E74 -> 280934.09 | D27: ='Monthly Model'!E80 -> -104235.65 | F27: 추천 보상은 동일인이 코드 2개를 보내 둘 다 카드 체험을 시작해야 발생합니다.
A28: M4 | B28: ='Monthly Model'!F52 -> 224869.09 | C28: ='Monthly Model'!F74 -> 284679.23 | D28: ='Monthly Model'!F80 -> -59810.138 | F28: 추천 무료월은 다음 달 사용, 미사용분 만료로 단순화했습니다.
A29: M5 | B29: ='Monthly Model'!G52 -> 271677.48 | C29: ='Monthly Model'!G74 -> 288275.28 | D29: ='Monthly Model'!G80 -> -16597.802 | F29: 오가닉 고객은 추천 코드 발급 대상에 포함하지 않았습니다.
A30: M6 | B30: ='Monthly Model'!H52 -> 318444.85 | C30: ='Monthly Model'!H74 -> 291812.85 | D30: ='Monthly Model'!H80 -> 26632.002 | F30: 음성 인식은 기기 내 처리. 외부 AI 요약은 텍스트 토큰 비용만 포함합니다.
A31: M7 | B31: ='Monthly Model'!I52 -> 365418.01 | C31: ='Monthly Model'!I74 -> 295330.07 | D31: ='Monthly Model'!I80 -> 70087.944 | F31: 비전 엔진 비용은 기본 0. 사용하려면 동의 비중과 실측 원가를 입력하세요.
A32: M8 | B32: ='Monthly Model'!J52 -> 412751.83 | C32: ='Monthly Model'!J74 -> 298854.26 | D32: ='Monthly Model'!J80 -> 113897.57 | F32: 매출은 VAT 제외, 고객 결제액과 카드 수수료는 VAT 포함 금액 기준입니다.
A33: M9 | B33: ='Monthly Model'!K52 -> 460592.24 | C33: ='Monthly Model'!K74 -> 302407.4 | D33: ='Monthly Model'!K80 -> 158184.84 | F33: 법인세는 월간 추정과 이월결손금 단순 적용. 실제 신고 세액과 다를 수 있습니다.
A34: M10 | B34: ='Monthly Model'!L52 -> 509083.69 | C34: ='Monthly Model'!L74 -> 306007.91 | D34: ='Monthly Model'!L80 -> 203075.78
A35: M11 | B35: ='Monthly Model'!M52 -> 558370.16 | C35: ='Monthly Model'!M74 -> 309671.78 | D35: ='Monthly Model'!M80 -> 248698.37
A36: M12 | B36: ='Monthly Model'!N52 -> 608595.68 | C36: ='Monthly Model'!N74 -> 313413.36 | D36: ='Monthly Model'!N80 -> 276780.62
A37: M13 | B37: ='Monthly Model'!O52 -> 659904.83 | C37: ='Monthly Model'!O74 -> 427245.86 | D37: ='Monthly Model'!O80 -> 209393.07
A38: M14 | B38: ='Monthly Model'!P52 -> 712443.15 | C38: ='Monthly Model'!P74 -> 321181.79 | D38: ='Monthly Model'!P80 -> 352135.23
A39: M15 | B39: ='Monthly Model'!Q52 -> 766357.64 | C39: ='Monthly Model'!Q74 -> 325233.25 | D39: ='Monthly Model'!Q80 -> 397011.95
A40: M16 | B40: ='Monthly Model'!R52 -> 821797.14 | C40: ='Monthly Model'!R74 -> 329412.1 | D40: ='Monthly Model'!R80 -> 443146.54
A41: M17 | B41: ='Monthly Model'!S52 -> 878912.83 | C41: ='Monthly Model'!S74 -> 333730.14 | D41: ='Monthly Model'!S80 -> 490664.43
A42: M18 | B42: ='Monthly Model'!T52 -> 937858.66 | C42: ='Monthly Model'!T74 -> 338199.22 | D42: ='Monthly Model'!T80 -> 539693.49
A43: M19 | B43: ='Monthly Model'!U52 -> 998791.76 | C43: ='Monthly Model'!U74 -> 342831.37 | D43: ='Monthly Model'!U80 -> 590364.35
A44: M20 | B44: ='Monthly Model'!V52 -> 1061872.9 | C44: ='Monthly Model'!V74 -> 347638.81 | D44: ='Monthly Model'!V80 -> 642810.73
A45: M21 | B45: ='Monthly Model'!W52 -> 1127267.1 | C45: ='Monthly Model'!W74 -> 352634.06 | D45: ='Monthly Model'!W80 -> 697169.77
...

Sheet Assumptions
A2: 사업모델 가정과 조절값
A4: 조절 항목 | B4: 단위 | C4: 값 | D4: 근거 구분 | E4: 출처 ID | F4: 정의 / 바꿀 때 확인할 점 | G4: 출시 후 1개월 | H4: 출시 후 2개월 | I4: 출시 후 3개월 | J4: 출시 후 4개월 | K4: 출시 후 5개월 | L4: 출시 후 6개월 | M4: 출시 후 7개월 | N4: 출시 후 8개월 | O4: 출시 후 9개월 | P4: 출시 후 10개월 | Q4: 출시 후 11개월 | R4: 출시 후 12개월
A5: 상품 · 체험 · 추천 규칙 | G5: 오가닉 계절 계수
A6: Essential 월 가격 | B6: 원 | C6: 21900 | D6: 사용자 | E6: U | F6: 부가세 포함 소비자 표시가 | G6: 1 | H6: 1 | I6: 1 | J6: 1 | K6: 1 | L6: 1 | M6: 1 | N6: 1 | O6: 1 | P6: 1 | Q6: 1 | R6: 1
A7: Essential 학생가 | B7: 원 | C7: 13900 | D7: 사용자 | E7: U | F7: 학생 인증 시 같은 기능
A8: Pro 월 가격 | B8: 원 | C8: 28900 | D8: 사용자 | E8: U | F8: 부가세 포함 소비자 표시가 | G8: 2년차에도 같은 계수를 반복합니다. 방학·개강 효과는 실측 후 입력하세요.
A9: 일반 무료체험 기간 | B9: 일 | C9: 14 | D9: 사용자 | E9: U | F9: 30일 이하는 다음 달 전환, 더 길면 해당 개월 수만큼 지연
A10: 체험 최대 이용량 | B10: 분 | C10: 150 | D10: 사용자 | E10: U | F10: 체험 사용량에 상한 적용 | G10: 가격 비중 합계 | H10: =SUM(C33,C34,C35) -> 1
A11: 1인당 초대 코드 | B11: 개 | C11: 2 | D11: 사용자 | E11: U | F11: 추천 보상은 두 코드가 모두 인정될 때 지급
A12: 사전예약 첫달 무료 | B12: 개월 | C12: 1 | D12: 사용자 | E12: U | F12: 카드 등록을 완료한 유료 플랜 이용자
A13: 추천 보상 무료 기간 | B13: 개월 | C13: 1 | D13: 사용자 | E13: U | F13: 한 추천인이 코드 2개 모두 달성 시 1회 지급
A14: 신규 유입 · 무료체험 전환
A15: 출시 시 사전예약자 | B15: 명 | C15: 25 | D15: 가정 | E15: A | F15: 현재 웨이트리스트 실측값으로 교체
A16: 사전예약 → 계정 가입 | B16: % | C16: 0.6 | D16: 가정 | E16: A | F16: 사전예약자 중 출시 후 가입 비중
A17: 사전예약 가입 → 카드 등록 | B17: % | C17: 0.7 | D17: 가정 | E17: A | F17: 첫달 무료 혜택 시작 비중
A18: 출시 첫달 오가닉 가입 | B18: 명 | C18: 20 | D18: 가정 | E18: A | F18: 광고·추천 제외. 실측 획득 채널로 교체
A19: 오가닉 월 성장률 | B19: % | C19: 0.05 | D19: 가정 | E19: A | F19: 아래 학사시즌 계수와 별도 적용
A20: 오가닉 가입 → 카드 체험 | B20: % | C20: 0.6 | D20: 가정 | E20: B1 | F20: 체험→유료 전환과 곱해야 가입→유료
A21: 추천 자격자 중 두 코드 공유 | B21: % | C21: 0.2 | D21: 참고 기반 가정 | E21: B3 | F21: 추천으로 유입된 고객의 공유율 참고. 본 제품 실측 아님
A22: 초대 코드 수신 → 가입 | B22: % | C22: 0.3 | D22: 참고 기반 가정 | E22: B3 | F22: 공유한 각 코드의 가입 확률
A23: 추천 가입 → 카드 체험 | B23: % | C23: 0.7 | D23: 가정 | E23: A | F23: 카드 등록 후 무료체험 시작이 추천 인정 조건
A24: 오가닉 카드 체험 → 유료 | B24: % | C24: 0.25 | D24: 가정 | E24: B1 | F24: 가입→유료 8.75%. 조사 수치는 6개월 기준이라 직접 비교 불가
A25: 추천 카드 체험 → 유료 | B25: % | C25: 0.25 | D25: 가정 | E25: B1 | F25: 체험 완료 다음 달부터 유료 과금
A26: 사전예약 첫달 무료 → 유료 | B26: % | C26: 0.4 | D26: 가정 | E26: A | F26: 무료 한 달 후 첫 결제 성공률
A27: 기존 고객 유지 · 가격 구성
A28: Essential 월 유료 이탈률 | B28: % | C28: 0.064 | D28: 벤치마크 | E28: B2 | F28: 저가 SaaS의 월 고객 이탈률 6.1~6.4% 참고
A29: 학생가 월 유료 이탈률 | B29: % | C29: 0.064 | D29: 벤치마크 | E29: B2 | F29: 방학 영향 미반영. 학사시즌 계수 조정 권장
A30: Pro 월 유료 이탈률 | B30: % | C30: 0.064 | D30: 벤치마크 | E30: B2 | F30: 계약/실측 전까지 동일 기본값
A31: Free 월 비활성 이탈률 | B31: % | C31: 0.3 | D31: 가정 | E31: A | F31: Free 계정 활성 사용자 재고의 이탈
A32: 유료 이탈 → Free 잔류 | B32: % | C32: 0.3 | D32: 가정 | E32: A | F32: 유료 해지 후 무료 사용자는 Free 재고로 이동
A33: 신규 유료 Essential 비중 | B33: % | C33: 0.4 | D33: 가정 | E33: A | F33: 학생가·Pro 비중과 합계 100%
A34: 신규 유료 학생가 비중 | B34: % | C34: 0.45 | D34: 가정 | E34: A | F34: 학생 타깃 특성 반영한 초기 가정
A35: 신규 유료 Pro 비중 | B35: % | C35: 0.15 | D35: 가정 | E35: A | F35: 나머지와 합계 100%
A36: 다음달 추천 보상 사용률 | B36: % | C36: 0.7 | D36: 가정 | E36: A | F36: 미사용분은 만료. 유료 구독 지속 여부 근사
A37: 활동량 · 추론 비용
A38: Essential 유료 월 평균 강의 | B38: 분 | C38: 200 | D38: 가정 | E38: A | F38: 제공 한도가 아닌 실제 평균 사용량
A39: 학생가 유료 월 평균 강의 | B39: 분 | C39: 200 | D39: 가정 | E39: A | F39: 제공 한도가 아닌 실제 평균 사용량
A40: Pro 유료 월 평균 강의 | B40: 분 | C40: 400 | D40: 가정 | E40: A | F40: 제공 한도가 아닌 실제 평균 사용량
A41: 체험 1인 평균 강의 | B41: 분 | C41: 80 | D41: 가정 | E41: A | F41: 200분 체험 상한 적용
A42: 사전예약 무료월 평균 강의 | B42: 분 | C42: 200 | D42: 가정 | E42: A | F42: 첫 달은 유료 플랜 기능 이용
...

Sheet Monthly Model
A2: 24개월 월별 가입 · 매출 · 손익
A4: 지표 | B4: 단위 | C4: M1 | D4: M2 | E4: M3 | F4: M4 | G4: M5 | H4: M6 | I4: M7 | J4: M8 | K4: M9 | L4: M10 | M4: M11 | N4: M12 | O4: M13 | P4: M14 | Q4: M15 | R4: M16 | S4: M17 | T4: M18 | U4: M19 | V4: M20 | W4: M21 | X4: M22 | Y4: M23 | Z4: M24
A5: 유입 · 카드 등록
A6: 출시 시 사전예약 명단 | B6: 명 | C6: =Assumptions!$C$15 -> 25 | D6: =0 -> 0 | E6: =0 -> 0 | F6: =0 -> 0 | G6: =0 -> 0 | H6: =0 -> 0 | I6: =0 -> 0 | J6: =0 -> 0 | K6: =0 -> 0 | ... Z6: =0 -> 0
A7: 사전예약 → 실제 가입 | B7: 명 | C7: =C6*Assumptions!$C$16 -> 15 | D7: =D6*Assumptions!$C$16 -> 0 | E7: =E6*Assumptions!$C$16 -> 0 | F7: =F6*Assumptions!$C$16 -> 0 | G7: =G6*Assumptions!$C$16 -> 0 | H7: =H6*Assumptions!$C$16 -> 0 | I7: =I6*Assumptions!$C$16 -> 0 | J7: =J6*Assumptions!$C$16 -> 0 | ... Z7: =Z6*Assumptions!$C$16 -> 0
A8: 사전예약 카드 등록 · 첫달 무료 | B8: 명 | C8: =C7*Assumptions!$C$17 -> 10.5 | D8: =D7*Assumptions!$C$17 -> 0 | E8: =E7*Assumptions!$C$17 -> 0 | F8: =F7*Assumptions!$C$17 -> 0 | G8: =G7*Assumptions!$C$17 -> 0 | H8: =H7*Assumptions!$C$17 -> 0 | I8: =I7*Assumptions!$C$17 -> 0 | J8: =J7*Assumptions!$C$17 -> 0 | ... Z8: =Z7*Assumptions!$C$17 -> 0
A9: 오가닉 신규 가입 | B9: 명 | C9: =Assumptions!$C$18*(1+Assumptions!$C$19)^0*Assumptions!$G$6 -> 20 | D9: =Assumptions!$C$18*(1+Assumptions!$C$19)^1*Assumptions!$H$6 -> 21 | E9: =Assumptions!$C$18*(1+Assumptions!$C$19)^2*Assumptions!$I$6 -> 22.05 | F9: =Assumptions!$C$18*(1+Assumptions!$C$19)^3*Assumptions!$J$6 -> 23.1525 | G9: =Assumptions!$C$18*(1+Assumptions!$C$19)^4*Assumptions!$K$6 -> 24.310125 | H9: =Assumptions!$C$18*(1+Assumptions!$C$19)^5*Assumptions!$L$6 -> 25.525631 | I9: =Assumptions!$C$18*(1+Assumptions!$C$19)^6*Assumptions!$M$6 -> 26.801913 | J9: =Assumptions!$C$18*(1+Assumptions!$C$19)^7*Assumptions!$N$6 -> 28.142008 | K9: =Assumptions!$C$18*(1+Assumptions!$C$19)^8*Assumptions!$O$6 -> 29.549109 | L9: =Assumptions!$C$18*(1+Assumptions!$C$19)^9*Assumptions!$P$6 -> 31.026564 | M9: =Assumptions!$C$18*(1+Assumptions!$C$19)^10*Assumptions!$Q$6 -> 32.577893 | N9: =Assumptions!$C$18*(1+Assumptions!$C$19)^11*Assumptions!$R$6 -> 34.206787 | O9: =Assumptions!$C$18*(1+Assumptions!$C$19)^12*Assumptions!$G$6 -> 35.917127 | P9: =Assumptions!$C$18*(1+Assumptions!$C$19)^13*Assumptions!$H$6 -> 37.712983 | Q9: =Assumptions!$C$18*(1+Assumptions!$C$19)^14*Assumptions!$I$6 -> 39.598632 | R9: =Assumptions!$C$18*(1+Assumptions!$C$19)^15*Assumptions!$J$6 -> 41.578564 | S9: =Assumptions!$C$18*(1+Assumptions!$C$19)^16*Assumptions!$K$6 -> 43.657492 | T9: =Assumptions!$C$18*(1+Assumptions!$C$19)^17*Assumptions!$L$6 -> 45.840366 | U9: =Assumptions!$C$18*(1+Assumptions!$C$19)^18*Assumptions!$M$6 -> 48.132385 | V9: =Assumptions!$C$18*(1+Assumptions!$C$19)^19*Assumptions!$N$6 -> 50.539004 | W9: =Assumptions!$C$18*(1+Assumptions!$C$19)^20*Assumptions!$O$6 -> 53.065954 | X9: =Assumptions!$C$18*(1+Assumptions!$C$19)^21*Assumptions!$P$6 -> 55.719252 | Y9: =Assumptions!$C$18*(1+Assumptions!$C$19)^22*Assumptions!$Q$6 -> 58.505214 | Z9: =Assumptions!$C$18*(1+Assumptions!$C$19)^23*Assumptions!$R$6 -> 61.430475
A10: 추천 코드 2개 공유자 | B10: 명 | C10: =0 -> 0 | D10: =(C8+C12)*Assumptions!$C$21 -> 2.1 | E10: =(D8+D12)*Assumptions!$C$21 -> 0.1764 | F10: =(E8+E12)*Assumptions!$C$21 -> 0.0148176 | G10: =(F8+F12)*Assumptions!$C$21 -> 0.0012446784 | H10: =(G8+G12)*Assumptions!$C$21 -> 0.00010455299 | I10: =(H8+H12)*Assumptions!$C$21 -> 8.7824508e-06 | J10: =(I8+I12)*Assumptions!$C$21 -> 7.3772587e-07 | K10: =(J8+J12)*Assumptions!$C$21 -> 6.1968973e-08 | ... Z10: =(Y8+Y12)*Assumptions!$C$21 -> 4.532769e-24
A11: 추천 코드 신규 가입 | B11: 명 | C11: =C10*Assumptions!$C$11*Assumptions!$C$22 -> 0 | D11: =D10*Assumptions!$C$11*Assumptions!$C$22 -> 1.26 | E11: =E10*Assumptions!$C$11*Assumptions!$C$22 -> 0.10584 | F11: =F10*Assumptions!$C$11*Assumptions!$C$22 -> 0.00889056 | G11: =G10*Assumptions!$C$11*Assumptions!$C$22 -> 0.00074680704 | H11: =H10*Assumptions!$C$11*Assumptions!$C$22 -> 6.2731791e-05 | I11: =I10*Assumptions!$C$11*Assumptions!$C$22 -> 5.2694705e-06 | J11: =J10*Assumptions!$C$11*Assumptions!$C$22 -> 4.4263552e-07 | ... Z11: =Z10*Assumptions!$C$11*Assumptions!$C$22 -> 2.7196614e-24
A12: 추천 카드 등록 체험 | B12: 명 | C12: =C11*Assumptions!$C$23 -> 0 | D12: =D11*Assumptions!$C$23 -> 0.882 | E12: =E11*Assumptions!$C$23 -> 0.074088 | F12: =F11*Assumptions!$C$23 -> 0.006223392 | G12: =G11*Assumptions!$C$23 -> 0.00052276493 | H12: =H11*Assumptions!$C$23 -> 4.3912254e-05 | I12: =I11*Assumptions!$C$23 -> 3.6886293e-06 | J12: =J11*Assumptions!$C$23 -> 3.0984486e-07 | ... Z12: =Z11*Assumptions!$C$23 -> 1.903763e-24
A13: 오가닉 카드 등록 체험 | B13: 명 | C13: =C9*Assumptions!$C$20 -> 12 | D13: =D9*Assumptions!$C$20 -> 12.6 | E13: =E9*Assumptions!$C$20 -> 13.23 | F13: =F9*Assumptions!$C$20 -> 13.8915 | G13: =G9*Assumptions!$C$20 -> 14.586075 | H13: =H9*Assumptions!$C$20 -> 15.315379 | I13: =I9*Assumptions!$C$20 -> 16.081148 | J13: =J9*Assumptions!$C$20 -> 16.885205 | ... Z13: =Z9*Assumptions!$C$20 -> 36.858285
A14: 전체 신규 가입 | B14: 명 | C14: =SUM(C7,C9,C11) -> 35 | D14: =SUM(D7,D9,D11) -> 22.26 | E14: =SUM(E7,E9,E11) -> 22.15584 | F14: =SUM(F7,F9,F11) -> 23.161391 | G14: =SUM(G7,G9,G11) -> 24.310872 | H14: =SUM(H7,H9,H11) -> 25.525694 | I14: =SUM(I7,I9,I11) -> 26.801918 | J14: =SUM(J7,J9,J11) -> 28.142009 | ... Z14: =SUM(Z7,Z9,Z11) -> 61.430475
A15: 신규 카드 등록 | B15: 명 | C15: =SUM(C8,C13,C12) -> 22.5 | D15: =SUM(D8,D13,D12) -> 13.482 | E15: =SUM(E8,E13,E12) -> 13.304088 | F15: =SUM(F8,F13,F12) -> 13.897723 | G15: =SUM(G8,G13,G12) -> 14.586598 | H15: =SUM(H8,H13,H12) -> 15.315423 | I15: =SUM(I8,I13,I12) -> 16.081151 | J15: =SUM(J8,J13,J12) -> 16.885205 | ... Z15: =SUM(Z8,Z13,Z12) -> 36.858285
A17: 가입 전환 · 고객 유지
A18: 오가닉 신규 유료 | B18: 명 | C18: =SUM(IF(0=MAX(1,ROUNDUP(Assumptions!$C$9/30,0)),C13*Assumptions!$C$24,0)) -> 0 | D18: =SUM(IF(1=MAX(1,ROUNDUP(Assumptions!$C$9/30,0)),C13*Assumptions!$C$24,0),IF(0=MAX(1,ROUNDUP(Assumptions!$C$9/30,0)),D13*Assumptions!$C$24,0)) -> 3 | E18: =SUM(IF(2=MAX(1,ROUNDUP(Assumptions!$C$9/30,0)),C13*Assumptions!$C$24,0),IF(1=MAX(1,ROUNDUP(Assumptions!$C$9/30,0)),D13*Assumptions!$C$24,0),IF(0=MAX(1,ROUNDUP(Assumptions!$C$9/30,0)),E13*Assumptions!$C$24,0)) -> 3.15 | F18: =SUM(IF(3=MAX(1,ROUNDUP(Assumptions!$C$9/30,0)),C13*Assumptions!$C$24,0),IF(2=MAX(1,ROUNDUP(Assumptions!$C$9/30,0)),D13*Assumptions!$C$24,0),IF(1=MAX(1,ROUNDUP(Assumptions!$C$9/30,0)),E13*Assumptions!$C$24,0),IF(0=MAX(1,ROUNDUP(Assumptions!$C$9/30,0)),F13*Assumptions!$C$24,0)) -> 3.3075 | G18: =SUM(IF(4=MAX(1,ROUNDUP(Assumptions!$C$9/30,0)),C13*Assumptions!$C$24,0),IF(3=MAX(1,ROUNDUP(Assumptions!$C$9/30,0)),D13*Assumptions!$C$24,0),IF(2=MAX(1,ROUNDUP(Assumptions!$C$9/30,0)),E13*Assumptions!$C$24,0),IF(1=MAX(1,ROUNDUP(Assumptions!$C$9/30,0)),F13*Assumptions!$C$24,0),IF(0=MAX(1,ROUNDUP(Assumptions!$C$9/30,0)),G13*Assumptions!$C$24,0)) -> 3.472875 | H18: =SUM(IF(5=MAX(1,ROUNDUP(Assumptions!$C$9/30,0)),C13*Assumptions!$C$24,0),IF(4=MAX(1,ROUNDUP(Assumptions!$C$9/30,0)),D13*Assumptions!$C$24,0),IF(3=MAX(1,ROUNDUP(Assumptions!$C$9/30,0)),E13*Assumptions!$C$24,0),IF(2=MAX(1,ROUNDUP(Assumptions!$C$9/30,0)),F13*Assumptions!$C$24,0),IF(1=MAX(1,ROUNDUP(Assumptions!$C$9/30,0)),G13*Assumptions!$C$24,0),IF(0=MAX(1,ROUNDUP(Assumptions!$C$9/30,0)),H13*Assumptions!$C$24,0)) -> 3.6465187 | I18: =SUM(IF(6=MAX(1,ROUNDUP(Assumptions!$C$9/30,0)),C13*Assumptions!$C$24,0),IF(5=MAX(1,ROUNDUP(Assumptions!$C$9/30,0)),D13*Assumptions!$C$24,0),IF(4=MAX(1,ROUNDUP(Assumptions!$C$9/30,0)),E13*Assumptions!$C$24,0),IF(3=MAX(1,ROUNDUP(Assumptions!$C$9/30,0)),F13*Assumptions!$C$24,0),IF(2=MAX(1,ROUNDUP(Assumptions!$C$9/30,0)),G13*Assumptions!$C$24,0),IF(1=MAX(1,ROUNDUP(Assumptions!$C$9/30,0)),H13*Assumptions!$C$24,0),IF(0=MAX(1,ROUNDUP(Assumptions!$C$9/30,0)),I13*Assumptions!$C$24,0)) -> 3.8288447 | J18: =SUM(IF(7=MAX(1,ROUNDUP(Assumptions!$C$9/30,0)),C13*Assumptions!$C$24,0),IF(6=MAX(1,ROUNDUP(Assumptions!$C$9/30,0)),D13*Assumptions!$C$24,0),IF(5=MAX(1,ROUNDUP(Assumptions!$C$9/30,0)),E13*Assumptions!$C$24,0),IF(4=MAX(1,ROUNDUP(Assumptions!$C$9/30,0)),F13*Assumptions!$C$24,0),IF(3=MAX(1,ROUNDUP(Assumptions!$C$9/30,0)),G13*Assumptions!$C$24,0),IF(2=MAX(1,ROUNDUP(Assumptions!$C$9/30,0)),H13*Assumptions!$C$24,0),IF(1=MAX(1,ROUNDUP(Assumptions!$C$9/30,0)),I13*Assumptions!$C$24,0),IF(0=MAX(1,ROUNDUP(Assumptions!$C$9/30,0)),J13*Assumptions!$C$24,0)) -> 4.0202869 | K18: =SUM(IF(8=MAX(1,ROUNDUP(Assumptions!$C$9/30,0)),C13*Assumptions!$C$24,0),IF(7=MAX(1,ROUNDUP(Assumptions!$C$9/30,0)),D13*Assumptions!$C$24,0),IF(6=MAX(1,ROUNDUP(Assumptions!$C$9/30,0)),E13*Assumptions!$C$24,0),IF(5=MAX(1,ROUNDUP(Assumptions!$C$9/30,0)),F13*Assumptions!$C$24,0),IF(4=MAX(1,ROUNDUP(Assumptions!$C$9/30,0)),G13*Assumptions!$C$24,0),IF(3=MAX(1,ROUNDUP(Assumptions!$C$9/30,0)),H13*Assumptions!$C$24,0),IF(2=MAX(1,ROUNDUP(Assumptions!$C$9/30,0)),I13*Assumptions!$C$24,0),IF(1=MAX(1,ROUNDUP(Assumptions!$C$9/30,0)),J13*Assumptions!$C$24,0),IF(0=MAX(1,ROUNDUP(Assumptions!$C$9/30,0)),K13*Assumptions!$C$24,0)) -> 4.2213013 | L18: =SUM(IF(9=MAX(1,ROUNDUP(Assumptions!$C$9/30,0)),C13*Assumptions!$C$24,0),IF(8=MAX(1,ROUNDUP(Assumptions!$C$9/30,0)),D13*Assumptions!$C$24,0),IF(7=MAX(1,ROUNDUP(Assumptions!$C$9/30,0)),E13*Assumptions!$C$24,0),IF(6=MAX(1,ROUNDUP(Assumptions!$C$9/30,0)),F13*Assumptions!$C$24,0),IF(5=MAX(1,ROUNDUP(Assumptions!$C$9/30,0)),G13*Assumptions!$C$24,0),IF(4=MAX(1,ROUNDUP(Assumptions!$C$9/30,0)),H13*Assumptions!$C$24,0),IF(3=MAX(1,ROUNDUP(Assumptions!$C$9/30,0)),I13*Assumptions!$C$24,0),IF(2=MAX(1,ROUNDUP(Assumptions!$C$9/30,0)),J13*Assumptions!$C$24,0),IF(1=MAX(1,ROUNDUP(Assumptions!$C$9/30,0)),K13*Assumptions!$C$24,0),IF(0=MAX(1,ROUNDUP(Assumptions!$C$9/30,0)),L13*Assumptions!$C$24,0)) -> 4.4323663 | M18: =SUM(IF(10=MAX(1,ROUNDUP(Assumptions!$C$9/30,0)),C13*Assumptions!$C$24,0),IF(9=MAX(1,ROUNDUP(Assumptions!$C$9/30,0)),D13*Assumptions!$C$24,0),IF(8=MAX(1,ROUNDUP(Assumptions!$C$9/30,0)),E13*Assumptions!$C$24,0),IF(7=MAX(1,ROUNDUP(Assumptions!$C$9/30,0)),F13*Assumptions!$C$24,0),IF(6=MAX(1,ROUNDUP(Assumptions!$C$9/30,0)),G13*Assumptions!$C$24,0),IF(5=MAX(1,ROUNDUP(Assumptions!$C$9/30,0)),H13*Assumptions!$C$24,0),IF(4=MAX(1,ROUNDUP(Assumptions!$C$9/30,0)),I13*Assumptions!$C$24,0),IF(3=MAX(1,ROUNDUP(Assumptions!$C$9/30,0)),J13*Assumptions!$C$24,0),IF(2=MAX(1,ROUNDUP(Assumptions!$C$9/30,0)),K13*Assumptions!$C$24,0),IF(1=MAX(1,ROUNDUP(Assumptions!$C$9/30,0)),L13*Assumptions!$C$24,0),IF(0=MAX(1,ROUNDUP(Assumptions!$C$9/30,0)),M13*Assumptions!$C$24,0)) -> 4.6539846 | N18: =SUM(IF(11=MAX(1,ROUNDUP(Assumptions!$C$9/30,0)),C13*Assumptions!$C$24,0),IF(10=MAX(1,ROUNDUP(Assumptions!$C$9/30,0)),D13*Assumptions!$C$24,0),IF(9=MAX(1,ROUNDUP(Assumptions!$C$9/30,0)),E13*Assumptions!$C$24,0),IF(8=MAX(1,ROUNDUP(Assumptions!$C$9/30,0)),F13*Assumptions!$C$24,0),IF(7=MAX(1,ROUNDUP(Assumptions!$C$9/30,0)),G13*Assumptions!$C$24,0),IF(6=MAX(1,ROUNDUP(Assumptions!$C$9/30,0)),H13*Assumptions!$C$24,0),IF(5=MAX(1,ROUNDUP(Assumptions!$C$9/30,0)),I13*Assumptions!$C$24,0),IF(4=MAX(1,ROUNDUP(Assumptions!$C$9/30,0)),J13*Assumptions!$C$24,0),IF(3=MAX(1,ROUNDUP(Assumptions!$C$9/30,0)),K13*Assumptions!$C$24,0),IF(2=MAX(1,ROUNDUP(Assumptions!$C$9/30,0)),L13*Assumptions!$C$24,0),IF(1=MAX(1,ROUNDUP(Assumptions!$C$9/30,0)),M13*Assumptions!$C$24,0),IF(0=MAX(1,ROUNDUP(Assumptions!$C$9/30,0)),N13*Assumptions!$C$24,0)) -> 4.8866839 | O18: =SUM(IF(12=MAX(1,ROUNDUP(Assumptions!$C$9/30,0)),C13*Assumptions!$C$24,0),IF(11=MAX(1,ROUNDUP(Assumptions!$C$9/30,0)),D13*Assumptions!$C$24,0),IF(10=MAX(1,ROUNDUP(Assumptions!$C$9/30,0)),E13*Assumptions!$C$24,0),IF(9=MAX(1,ROUNDUP(Assumptions!$C$9/30,0)),F13*Assumptions!$C$24,0),IF(8=MAX(1,ROUNDUP(Assumptions!$C$9/30,0)),G13*Assumptions!$C$24,0),IF(7=MAX(1,ROUNDUP(Assumptions!$C$9/30,0)),H13*Assumptions!$C$24,0),IF(6=MAX(1,ROUNDUP(Assumptions!$C$9/30,0)),I13*Assumptions!$C$24,0),IF(5=MAX(1,ROUNDUP(Assumptions!$C$9/30,0)),J13*Assumptions!$C$24,0),IF(4=MAX(1,ROUNDUP(Assumptions!$C$9/30,0)),K13*Assumptions!$C$24,0),IF(3=MAX(1,ROUNDUP(Assumptions!$C$9/30,0)),L13*Assumptions!$C$24,0),IF(2=MAX(1,ROUNDUP(Assumptions!$C$9/30,0)),M13*Assumptions!$C$24,0),IF(1=MAX(1,ROUNDUP(Assumptions!$C$9/30,0)),N13*Assumptions!$C$24,0),IF(0=MAX(1,ROUNDUP(Assumptions!$C$9/30,0)),O13*Assumptions!$C$24,0)) -> 5.1310181 | P18: =SUM(IF(13=MAX(1,ROUNDUP(Assumptions!$C$9/30,0)),C13*Assumptions!$C$24,0),IF(12=MAX(1,ROUNDUP(Assumptions!$C$9/30,0)),D13*Assumptions!$C$24,0),IF(11=MAX(1,ROUNDUP(Assumptions!$C$9/30,0)),E13*Assumptions!$C$24,0),IF(10=MAX(1,ROUNDUP(Assumptions!$C$9/30,0)),F13*Assumptions!$C$24,0),IF(9=MAX(1,ROUNDUP(Assumptions!$C$9/30,0)),G13*Assumptions!$C$24,0),IF(8=MAX(1,ROUNDUP(Assumptions!$C$9/30,0)),H13*Assumptions!$C$24,0),IF(7=MAX(1,ROUNDUP(Assumptions!$C$9/30,0)),I13*Assumptions!$C$24,0),IF(6=MAX(1,ROUNDUP(Assumptions!$C$9/30,0)),J13*Assumptions!$C$24,0),IF(5=MAX(1,ROUNDUP(Assumptions!$C$9/30,0)),K13*Assumptions!$C$24,0),IF(4=MAX(1,ROUNDUP(Assumptions!$C$9/30,0)),L13*Assumptions!$C$24,0),IF(3=MAX(1,ROUNDUP(Assumptions!$C$9/30,0)),M13*Assumptions!$C$24,0),IF(2=MAX(1,ROUNDUP(Assumptions!$C$9/30,0)),N13*Assumptions!$C$24,0),IF(1=MAX(1,ROUNDUP(Assumptions!$C$9/30,0)),O13*Assumptions!$C$24,0),IF(0=MAX(1,ROUNDUP(Assumptions!$C$9/30,0)),P13*Assumptions!$C$24,0)) -> 5.387569 | Q18: =SUM(IF(14=MAX(1,ROUNDUP(Assumptions!$C$9/30,0)),C13*Assumptions!$C$24,0),IF(13=MAX(1,ROUNDUP(Assumptions!$C$9/30,0)),D13*Assumptions!$C$24,0),IF(12=MAX(1,ROUNDUP(Assumptions!$C$9/30,0)),E13*Assumptions!$C$24,0),IF(11=MAX(1,ROUNDUP(Assumptions!$C$9/30,0)),F13*Assumptions!$C$24,0),IF(10=MAX(1,ROUNDUP(Assumptions!$C$9/30,0)),G13*Assumptions!$C$24,0),IF(9=MAX(1,ROUNDUP(Assumptions!$C$9/30,0)),H13*Assumptions!$C$24,0),IF(8=MAX(1,ROUNDUP(Assumptions!$C$9/30,0)),I13*Assumptions!$C$24,0),IF(7=MAX(1,ROUNDUP(Assumptions!$C$9/30,0)),J13*Assumptions!$C$24,0),IF(6=MAX(1,ROUNDUP(Assumptions!$C$9/30,0)),K13*Assumptions!$C$24,0),IF(5=MAX(1,ROUNDUP(Assumptions!$C$9/30,0)),L13*Assumptions!$C$24,0),IF(4=MAX(1,ROUNDUP(Assumptions!$C$9/30,0)),M13*Assumptions!$C$24,0),IF(3=MAX(1,ROUNDUP(Assumptions!$C$9/30,0)),N13*Assumptions!$C$24,0),IF(2=MAX(1,ROUNDUP(Assumptions!$C$9/30,0)),O13*Assumptions!$C$24,0),IF(1=MAX(1,ROUNDUP(Assumptions!$C$9/30,0)),P13*Assumptions!$C$24,0),IF(0=MAX(1,ROUNDUP(Assumptions!$C$9/30,0)),Q13*Assumptions!$C$24,0)) -> 5.6569474 | R18: =SUM(IF(15=MAX(1,ROUNDUP(Assumptions!$C$9/30,0)),C13*Assumptions!$C$24,0),IF(14=MAX(1,ROUNDUP(Assumptions!$C$9/30,0)),D13*Assumptions!$C$24,0),IF(13=MAX(1,ROUNDUP(Assumptions!$C$9/30,0)),E13*Assumptions!$C$24,0),IF(12=MAX(1,ROUNDUP(Assumptions!$C$9/30,0)),F13*Assumptions!$C$24,0),IF(11=MAX(1,ROUNDUP(Assumptions!$C$9/30,0)),G13*Assumptions!$C$24,0),IF(10=MAX(1,ROUNDUP(Assumptions!$C$9/30,0)),H13*Assumptions!$C$24,0),IF(9=MAX(1,ROUNDUP(Assumptions!$C$9/30,0)),I13*Assumptions!$C$24,0),IF(8=MAX(1,ROUNDUP(Assumptions!$C$9/30,0)),J13*Assumptions!$C$24,0),IF(7=MAX(1,ROUNDUP(Assumptions!$C$9/30,0)),K13*Assumptions!$C$24,0),IF(6=MAX(1,ROUNDUP(Assumptions!$C$9/30,0)),L13*Assumptions!$C$24,0),IF(5=MAX(1,ROUNDUP(Assumptions!$C$9/30,0)),M13*Assumptions!$C$24,0),IF(4=MAX(1,ROUNDUP(Assumptions!$C$9/30,0)),N13*Assumptions!$C$24,0),IF(3=MAX(1,ROUNDUP(Assumptions!$C$9/30,0)),O13*Assumptions!$C$24,0),IF(2=MAX(1,ROUNDUP(Assumptions!$C$9/30,0)),P13*Assumptions!$C$24,0),IF(1=MAX(1,ROUNDUP(Assumptions!$C$9/30,0)),Q13*Assumptions!$C$24,0),IF(0=MAX(1,ROUNDUP(Assumptions!$C$9/30,0)),R13*Assumptions!$C$24,0)) -> 5.9397948 | S18: =SUM(IF(16=MAX(1,ROUNDUP(Assumptions!$C$9/30,0)),C13*Assumptions!$C$24,0),IF(15=MAX(1,ROUNDUP(Assumptions!$C$9/30,0)),D13*Assumptions!$C$24,0),IF(14=MAX(1,ROUNDUP(Assumptions!$C$9/30,0)),E13*Assumptions!$C$24,0),IF(13=MAX(1,ROUNDUP(Assumptions!$C$9/30,0)),F13*Assumptions!$C$24,0),IF(12=MAX(1,ROUNDUP(Assumptions!$C$9/30,0)),G13*Assumptions!$C$24,0),IF(11=MAX(1,ROUNDUP(Assumptions!$C$9/30,0)),H13*Assumptions!$C$24,0),IF(10=MAX(1,ROUNDUP(Assumptions!$C$9/30,0)),I13*Assumptions!$C$24,0),IF(9=MAX(1,ROUNDUP(Assumptions!$C$9/30,0)),J13*Assumptions!$C$24,0),IF(8=MAX(1,ROUNDUP(Assumptions!$C$9/30,0)),K13*Assumptions!$C$24,0),IF(7=MAX(1,ROUNDUP(Assumptions!$C$9/30,0)),L13*Assumptions!$C$24,0),IF(6=MAX(1,ROUNDUP(Assumptions!$C$9/30,0)),M13*Assumptions!$C$24,0),IF(5=MAX(1,ROUNDUP(Assumptions!$C$9/30,0)),N13*Assumptions!$C$24,0),IF(4=MAX(1,ROUNDUP(Assumptions!$C$9/30,0)),O13*Assumptions!$C$24,0),IF(3=MAX(1,ROUNDUP(Assumptions!$C$9/30,0)),P13*Assumptions!$C$24,0),IF(2=MAX(1,ROUNDUP(Assumptions!$C$9/30,0)),Q13*Assumptions!$C$24,0),IF(1=MAX(1,ROUNDUP(Assumptions!$C$9/30,0)),R13*Assumptions!$C$24,0),IF(0=MAX(1,ROUNDUP(Assumptions!$C$9/30,0)),S13*Assumptions!$C$24,0)) -> 6.2367845 | T18: =SUM(IF(17=MAX(1,ROUNDUP(Assumptions!$C$9/30,0)),C13*Assumptions!$C$24,0),IF(16=MAX(1,ROUNDUP(Assumptions!$C$9/30,0)),D13*Assumptions!$C$24,0),IF(15=MAX(1,ROUNDUP(Assumptions!$C$9/30,0)),E13*Assumptions!$C$24,0),IF(14=MAX(1,ROUNDUP(Assumptions!$C$9/30,0)),F13*Assumptions!$C$24,0),IF(13=MAX(1,ROUNDUP(Assumptions!$C$9/30,0)),G13*Assumptions!$C$24,0),IF(12=MAX(1,ROUNDUP(Assumptions!$C$9/30,0)),H13*Assumptions!$C$24,0),IF(11=MAX(1,ROUNDUP(Assumptions!$C$9/30,0)),I13*Assumptions!$C$24,0),IF(10=MAX(1,ROUNDUP(Assumptions!$C$9/30,0)),J13*Assumptions!$C$24,0),IF(9=MAX(1,ROUNDUP(Assumptions!$C$9/30,0)),K13*Assumptions!$C$24,0),IF(8=MAX(1,ROUNDUP(Assumptions!$C$9/30,0)),L13*Assumptions!$C$24,0),IF(7=MAX(1,ROUNDUP(Assumptions!$C$9/30,0)),M13*Assumptions!$C$24,0),IF(6=MAX(1,ROUNDUP(Assumptions!$C$9/30,0)),N13*Assumptions!$C$24,0),IF(5=MAX(1,ROUNDUP(Assumptions!$C$9/30,0)),O13*Assumptions!$C$24,0),IF(4=MAX(1,ROUNDUP(Assumptions!$C$9/30,0)),P13*Assumptions!$C$24,0),IF(3=MAX(1,ROUNDUP(Assumptions!$C$9/30,0)),Q13*Assumptions!$C$24,0),IF(2=MAX(1,ROUNDUP(Assumptions!$C$9/30,0)),R13*Assumptions!$C$24,0),IF(1=MAX(1,ROUNDUP(Assumptions!$C$9/30,0)),S13*Assumptions!$C$24,0),IF(0=MAX(1,ROUNDUP(Assumptions!$C$9/30,0)),T13*Assumptions!$C$24,0)) -> 6.5486238 | U18: =SUM(IF(18=MAX(1,ROUNDUP(Assumptions!$C$9/30,0)),C13*Assumptions!$C$24,0),IF(17=MAX(1,ROUNDUP(Assumptions!$C$9/30,0)),D13*Assumptions!$C$24,0),IF(16=MAX(1,ROUNDUP(Assumptions!$C$9/30,0)),E13*Assumptions!$C$24,0),IF(15=MAX(1,ROUNDUP(Assumptions!$C$9/30,0)),F13*Assumptions!$C$24,0),IF(14=MAX(1,ROUNDUP(Assumptions!$C$9/30,0)),G13*Assumptions!$C$24,0),IF(13=MAX(1,ROUNDUP(Assumptions!$C$9/30,0)),H13*Assumptions!$C$24,0),IF(12=MAX(1,ROUNDUP(Assumptions!$C$9/30,0)),I13*Assumptions!$C$24,0),IF(11=MAX(1,ROUNDUP(Assumptions!$C$9/30,0)),J13*Assumptions!$C$24,0),IF(10=MAX(1,ROUNDUP(Assumptions!$C$9/30,0)),K13*Assumptions!$C$24,0),IF(9=MAX(1,ROUNDUP(Assumptions!$C$9/30,0)),L13*Assumptions!$C$24,0),IF(8=MAX(1,ROUNDUP(Assumptions!$C$9/30,0)),M13*Assumptions!$C$24,0),IF(7=MAX(1,ROUNDUP(Assumptions!$C$9/30,0)),N13*Assumptions!$C$24,0),IF(6=MAX(1,ROUNDUP(Assumptions!$C$9/30,0)),O13*Assumptions!$C$24,0),IF(5=MAX(1,ROUNDUP(Assumptions!$C$9/30,0)),P13*Assumptions!$C$24,0),IF(4=MAX(1,ROUNDUP(Assumptions!$C$9/30,0)),Q13*Assumptions!$C$24,0),IF(3=MAX(1,ROUNDUP(Assumptions!$C$9/30,0)),R13*Assumptions!$C$24,0),IF(2=MAX(1,ROUNDUP(Assumptions!$C$9/30,0)),S13*Assumptions!$C$24,0),IF(1=MAX(1,ROUNDUP(Assumptions!$C$9/30,0)),T13*Assumptions!$C$24,0),IF(0=MAX(1,ROUNDUP(Assumptions!$C$9/30,0)),U13*Assumptions!$C$24,0)) -> 6.876055 | V18: =SUM(IF(19=MAX(1,ROUNDUP(Assumptions!$C$9/30,0)),C13*Assumptions!$C$24,0),IF(18=MAX(1,ROUNDUP(Assumptions!$C$9/30,0)),D13*Assumptions!$C$24,0),IF(17=MAX(1,ROUNDUP(Assumptions!$C$9/30,0)),E13*Assumptions!$C$24,0),IF(16=MAX(1,ROUNDUP(Assumptions!$C$9/30,0)),F13*Assumptions!$C$24,0),IF(15=MAX(1,ROUNDUP(Assumptions!$C$9/30,0)),G13*Assumptions!$C$24,0),IF(14=MAX(1,ROUNDUP(Assumptions!$C$9/30,0)),H13*Assumptions!$C$24,0),IF(13=MAX(1,ROUNDUP(Assumptions!$C$9/30,0)),I13*Assumptions!$C$24,0),IF(12=MAX(1,ROUNDUP(Assumptions!$C$9/30,0)),J13*Assumptions!$C$24,0),IF(11=MAX(1,ROUNDUP(Assumptions!$C$9/30,0)),K13*Assumptions!$C$24,0),IF(10=MAX(1,ROUNDUP(Assumptions!$C$9/30,0)),L13*Assumptions!$C$24,0),IF(9=MAX(1,ROUNDUP(Assumptions!$C$9/30,0)),M13*Assumptions!$C$24,0),IF(8=MAX(1,ROUNDUP(Assumptions!$C$9/30,0)),N13*Assumptions!$C$24,0),IF(7=MAX(1,ROUNDUP(Assumptions!$C$9/30,0)),O13*Assumptions!$C$24,0),IF(6=MAX(1,ROUNDUP(Assumptions!$C$9/30,0)),P13*Assumptions!$C$24,0),IF(5=MAX(1,ROUNDUP(Assumptions!$C$9/30,0)),Q13*Assumptions!$C$24,0),IF(4=MAX(1,ROUNDUP(Assumptions!$C$9/30,0)),R13*Assumptions!$C$24,0),IF(3=MAX(1,ROUNDUP(Assumptions!$C$9/30,0)),S13*Assumptions!$C$24,0),IF(2=MAX(1,ROUNDUP(Assumptions!$C$9/30,0)),T13*Assumptions!$C$24,0),IF(1=MAX(1,ROUNDUP(Assumptions!$C$9/30,0)),U13*Assumptions!$C$24,0),IF(0=MAX(1,ROUNDUP(Assumptions!$C$9/30,0)),V13*Assumptions!$C$24,0)) -> 7.2198577 | W18: =SUM(IF(20=MAX(1,ROUNDUP(Assumptions!$C$9/30,0)),C13*Assumptions!$C$24,0),IF(19=MAX(1,ROUNDUP(Assumptions!$C$9/30,0)),D13*Assumptions!$C$24,0),IF(18=MAX(1,ROUNDUP(Assumptions!$C$9/30,0)),E13*Assumptions!$C$24,0),IF(17=MAX(1,ROUNDUP(Assumptions!$C$9/30,0)),F13*Assumptions!$C$24,0),IF(16=MAX(1,ROUNDUP(Assumptions!$C$9/30,0)),G13*Assumptions!$C$24,0),IF(15=MAX(1,ROUNDUP(Assumptions!$C$9/30,0)),H13*Assumptions!$C$24,0),IF(14=MAX(1,ROUNDUP(Assumptions!$C$9/30,0)),I13*Assumptions!$C$24,0),IF(13=MAX(1,ROUNDUP(Assumptions!$C$9/30,0)),J13*Assumptions!$C$24,0),IF(12=MAX(1,ROUNDUP(Assumptions!$C$9/30,0)),K13*Assumptions!$C$24,0),IF(11=MAX(1,ROUNDUP(Assumptions!$C$9/30,0)),L13*Assumptions!$C$24,0),IF(10=MAX(1,ROUNDUP(Assumptions!$C$9/30,0)),M13*Assumptions!$C$24,0),IF(9=MAX(1,ROUNDUP(Assumptions!$C$9/30,0)),N13*Assumptions!$C$24,0),IF(8=MAX(1,ROUNDUP(Assumptions!$C$9/30,0)),O13*Assumptions!$C$24,0),IF(7=MAX(1,ROUNDUP(Assumptions!$C$9/30,0)),P13*Assumptions!$C$24,0),IF(6=MAX(1,ROUNDUP(Assumptions!$C$9/30,0)),Q13*Assumptions!$C$24,0),IF(5=MAX(1,ROUNDUP(Assumptions!$C$9/30,0)),R13*Assumptions!$C$24,0),IF(4=MAX(1,ROUNDUP(Assumptions!$C$9/30,0)),S13*Assumptions!$C$24,0),IF(3=MAX(1,ROUNDUP(Assumptions!$C$9/30,0)),T13*Assumptions!$C$24,0),IF(2=MAX(1,ROUNDUP(Assumptions!$C$9/30,0)),U13*Assumptions!$C$24,0),IF(1=MAX(1,ROUNDUP(Assumptions!$C$9/30,0)),V13*Assumptions!$C$24,0),IF(0=MAX(1,ROUNDUP(Assumptions!$C$9/30,0)),W13*Assumptions!$C$24,0)) -> 7.5808506 | X18: =SUM(IF(21=MAX(1,ROUNDUP(Assumptions!$C$9/30,0)),C13*Assumptions!$C$24,0),IF(20=MAX(1,ROUNDUP(Assumptions!$C$9/30,0)),D13*Assumptions!$C$24,0),IF(19=MAX(1,ROUNDUP(Assumptions!$C$9/30,0)),E13*Assumptions!$C$24,0),IF(18=MAX(1,ROUNDUP(Assumptions!$C$9/30,0)),F13*Assumptions!$C$24,0),IF(17=MAX(1,ROUNDUP(Assumptions!$C$9/30,0)),G13*Assumptions!$C$24,0),IF(16=MAX(1,ROUNDUP(Assumptions!$C$9/30,0)),H13*Assumptions!$C$24,0),IF(15=MAX(1,ROUNDUP(Assumptions!$C$9/30,0)),I13*Assumptions!$C$24,0),IF(14=MAX(1,ROUNDUP(Assumptions!$C$9/30,0)),J13*Assumptions!$C$24,0),IF(13=MAX(1,ROUNDUP(Assumptions!$C$9/30,0)),K13*Assumptions!$C$24,0),IF(12=MAX(1,ROUNDUP(Assumptions!$C$9/30,0)),L13*Assumptions!$C$24,0),IF(11=MAX(1,ROUNDUP(Assumptions!$C$9/30,0)),M13*Assumptions!$C$24,0),IF(10=MAX(1,ROUNDUP(Assumptions!$C$9/30,0)),N13*Assumptions!$C$24,0),IF(9=MAX(1,ROUNDUP(Assumptions!$C$9/30,0)),O13*Assumptions!$C$24,0),IF(8=MAX(1,ROUNDUP(Assumptions!$C$9/30,0)),P13*Assumptions!$C$24,0),IF(7=MAX(1,ROUNDUP(Assumptions!$C$9/30,0)),Q13*Assumptions!$C$24,0),IF(6=MAX(1,ROUNDUP(Assumptions!$C$9/30,0)),R13*Assumptions!$C$24,0),IF(5=MAX(1,ROUNDUP(Assumptions!$C$9/30,0)),S13*Assumptions!$C$24,0),IF(4=MAX(1,ROUNDUP(Assumptions!$C$9/30,0)),T13*Assumptions!$C$24,0),IF(3=MAX(1,ROUNDUP(Assumptions!$C$9/30,0)),U13*Assumptions!$C$24,0),IF(2=MAX(1,ROUNDUP(Assumptions!$C$9/30,0)),V13*Assumptions!$C$24,0),IF(1=MAX(1,ROUNDUP(Assumptions!$C$9/30,0)),W13*Assumptions!$C$24,0),IF(0=MAX(1,ROUNDUP(Assumptions!$C$9/30,0)),X13*Assumptions!$C$24,0)) -> 7.9598931 | Y18: =SUM(IF(22=MAX(1,ROUNDUP(Assumptions!$C$9/30,0)),C13*Assumptions!$C$24,0),IF(21=MAX(1,ROUNDUP(Assumptions!$C$9/30,0)),D13*Assumptions!$C$24,0),IF(20=MAX(1,ROUNDUP(Assumptions!$C$9/30,0)),E13*Assumptions!$C$24,0),IF(19=MAX(1,ROUNDUP(Assumptions!$C$9/30,0)),F13*Assumptions!$C$24,0),IF(18=MAX(1,ROUNDUP(Assumptions!$C$9/30,0)),G13*Assumptions!$C$24,0),IF(17=MAX(1,ROUNDUP(Assumptions!$C$9/30,0)),H13*Assumptions!$C$24,0),IF(16=MAX(1,ROUNDUP(Assumptions!$C$9/30,0)),I13*Assumptions!$C$24,0),IF(15=MAX(1,ROUNDUP(Assumptions!$C$9/30,0)),J13*Assumptions!$C$24,0),IF(14=MAX(1,ROUNDUP(Assumptions!$C$9/30,0)),K13*Assumptions!$C$24,0),IF(13=MAX(1,ROUNDUP(Assumptions!$C$9/30,0)),L13*Assumptions!$C$24,0),IF(12=MAX(1,ROUNDUP(Assumptions!$C$9/30,0)),M13*Assumptions!$C$24,0),IF(11=MAX(1,ROUNDUP(Assumptions!$C$9/30,0)),N13*Assumptions!$C$24,0),IF(10=MAX(1,ROUNDUP(Assumptions!$C$9/30,0)),O13*Assumptions!$C$24,0),IF(9=MAX(1,ROUNDUP(Assumptions!$C$9/30,0)),P13*Assumptions!$C$24,0),IF(8=MAX(1,ROUNDUP(Assumptions!$C$9/30,0)),Q13*Assumptions!$C$24,0),IF(7=MAX(1,ROUNDUP(Assumptions!$C$9/30,0)),R13*Assumptions!$C$24,0),IF(6=MAX(1,ROUNDUP(Assumptions!$C$9/30,0)),S13*Assumptions!$C$24,0),IF(5=MAX(1,ROUNDUP(Assumptions!$C$9/30,0)),T13*Assumptions!$C$24,0),IF(4=MAX(1,ROUNDUP(Assumptions!$C$9/30,0)),U13*Assumptions!$C$24,0),IF(3=MAX(1,ROUNDUP(Assumptions!$C$9/30,0)),V13*Assumptions!$C$24,0),IF(2=MAX(1,ROUNDUP(Assumptions!$C$9/30,0)),W13*Assumptions!$C$24,0),IF(1=MAX(1,ROUNDUP(Assumptions!$C$9/30,0)),X13*Assumptions!$C$24,0),IF(0=MAX(1,ROUNDUP(Assumptions!$C$9/30,0)),Y13*Assumptions!$C$24,0)) -> 8.3578878 | Z18: =SUM(IF(23=MAX(1,ROUNDUP(Assumptions!$C$9/30,0)),C13*Assumptions!$C$24,0),IF(22=MAX(1,ROUNDUP(Assumptions!$C$9/30,0)),D13*Assumptions!$C$24,0),IF(21=MAX(1,ROUNDUP(Assumptions!$C$9/30,0)),E13*Assumptions!$C$24,0),IF(20=MAX(1,ROUNDUP(Assumptions!$C$9/30,0)),F13*Assumptions!$C$24,0),IF(19=MAX(1,ROUNDUP(Assumptions!$C$9/30,0)),G13*Assumptions!$C$24,0),IF(18=MAX(1,ROUNDUP(Assumptions!$C$9/30,0)),H13*Assumptions!$C$24,0),IF(17=MAX(1,ROUNDUP(Assumptions!$C$9/30,0)),I13*Assumptions!$C$24,0),IF(16=MAX(1,ROUNDUP(Assumptions!$C$9/30,0)),J13*Assumptions!$C$24,0),IF(15=MAX(1,ROUNDUP(Assumptions!$C$9/30,0)),K13*Assumptions!$C$24,0),IF(14=MAX(1,ROUNDUP(Assumptions!$C$9/30,0)),L13*Assumptions!$C$24,0),IF(13=MAX(1,ROUNDUP(Assumptions!$C$9/30,0)),M13*Assumptions!$C$24,0),IF(12=MAX(1,ROUNDUP(Assumptions!$C$9/30,0)),N13*Assumptions!$C$24,0),IF(11=MAX(1,ROUNDUP(Assumptions!$C$9/30,0)),O13*Assumptions!$C$24,0),IF(10=MAX(1,ROUNDUP(Assumptions!$C$9/30,0)),P13*Assumptions!$C$24,0),IF(9=MAX(1,ROUNDUP(Assumptions!$C$9/30,0)),Q13*Assumptions!$C$24,0),IF(8=MAX(1,ROUNDUP(Assumptions!$C$9/30,0)),R13*Assumptions!$C$24,0),IF(7=MAX(1,ROUNDUP(Assumptions!$C$9/30,0)),S13*Assumptions!$C$24,0),IF(6=MAX(1,ROUNDUP(Assumptions!$C$9/30,0)),T13*Assumptions!$C$24,0),IF(5=MAX(1,ROUNDUP(Assumptions!$C$9/30,0)),U13*Assumptions!$C$24,0),IF(4=MAX(1,ROUNDUP(Assumptions!$C$9/30,0)),V13*Assumptions!$C$24,0),IF(3=MAX(1,ROUNDUP(Assumptions!$C$9/30,0)),W13*Assumptions!$C$24,0),IF(2=MAX(1,ROUNDUP(Assumptions!$C$9/30,0)),X13*Assumptions!$C$24,0),IF(1=MAX(1,ROUNDUP(Assumptions!$C$9/30,0)),Y13*Assumptions!$C$24,0),IF(0=MAX(1,ROUNDUP(Assumptions!$C$9/30,0)),Z13*Assumptions!$C$24,0)) -> 8.7757822
A19: 추천 신규 유료 | B19: 명 | C19: =SUM(IF(0=MAX(1,ROUNDUP(Assumptions!$C$9/30,0)),C12*Assumptions!$C$25,0)) -> 0 | D19: =SUM(IF(1=MAX(1,ROUNDUP(Assumptions!$C$9/30,0)),C12*Assumptions!$C$25,0),IF(0=MAX(1,ROUNDUP(Assumptions!$C$9/30,0)),D12*Assumptions!$C$25,0)) -> 0 | E19: =SUM(IF(2=MAX(1,ROUNDUP(Assumptions!$C$9/30,0)),C12*Assumptions!$C$25,0),IF(1=MAX(1,ROUNDUP(Assumptions!$C$9/30,0)),D12*Assumptions!$C$25,0),IF(0=MAX(1,ROUNDUP(Assumptions!$C$9/30,0)),E12*Assumptions!$C$25,0)) -> 0.2205 | F19: =SUM(IF(3=MAX(1,ROUNDUP(Assumptions!$C$9/30,0)),C12*Assumptions!$C$25,0),IF(2=MAX(1,ROUNDUP(Assumptions!$C$9/30,0)),D12*Assumptions!$C$25,0),IF(1=MAX(1,ROUNDUP(Assumptions!$C$9/30,0)),E12*Assumptions!$C$25,0),IF(0=MAX(1,ROUNDUP(Assumptions!$C$9/30,0)),F12*Assumptions!$C$25,0)) -> 0.018522 | G19: =SUM(IF(4=MAX(1,ROUNDUP(Assumptions!$C$9/30,0)),C12*Assumptions!$C$25,0),IF(3=MAX(1,ROUNDUP(Assumptions!$C$9/30,0)),D12*Assumptions!$C$25,0),IF(2=MAX(1,ROUNDUP(Assumptions!$C$9/30,0)),E12*Assumptions!$C$25,0),IF(1=MAX(1,ROUNDUP(Assumptions!$C$9/30,0)),F12*Assumptions!$C$25,0),IF(0=MAX(1,ROUNDUP(Assumptions!$C$9/30,0)),G12*Assumptions!$C$25,0)) -> 0.001555848 | H19: =SUM(IF(5=MAX(1,ROUNDUP(Assumptions!$C$9/30,0)),C12*Assumptions!$C$25,0),IF(4=MAX(1,ROUNDUP(Assumptions!$C$9/30,0)),D12*Assumptions!$C$25,0),IF(3=MAX(1,ROUNDUP(Assumptions!$C$9/30,0)),E12*Assumptions!$C$25,0),IF(2=MAX(1,ROUNDUP(Assumptions!$C$9/30,0)),F12*Assumptions!$C$25,0),IF(1=MAX(1,ROUNDUP(Assumptions!$C$9/30,0)),G12*Assumptions!$C$25,0),IF(0=MAX(1,ROUNDUP(Assumptions!$C$9/30,0)),H12*Assumptions!$C$25,0)) -> 0.00013069123 | I19: =SUM(IF(6=MAX(1,ROUNDUP(Assumptions!$C$9/30,0)),C12*Assumptions!$C$25,0),IF(5=MAX(1,ROUNDUP(Assumptions!$C$9/30,0)),D12*Assumptions!$C$25,0),IF(4=MAX(1,ROUNDUP(Assumptions!$C$9/30,0)),E12*Assumptions!$C$25,0),IF(3=MAX(1,ROUNDUP(Assumptions!$C$9/30,0)),F12*Assumptions!$C$25,0),IF(2=MAX(1,ROUNDUP(Assumptions!$C$9/30,0)),G12*Assumptions!$C$25,0),IF(1=MAX(1,ROUNDUP(Assumptions!$C$9/30,0)),H12*Assumptions!$C$25,0),IF(0=MAX(1,ROUNDUP(Assumptions!$C$9/30,0)),I12*Assumptions!$C$25,0)) -> 1.0978063e-05 | J19: =SUM(IF(7=MAX(1,ROUNDUP(Assumptions!$C$9/30,0)),C12*Assumptions!$C$25,0),IF(6=MAX(1,ROUNDUP(Assumptions!$C$9/30,0)),D12*Assumptions!$C$25,0),IF(5=MAX(1,ROUNDUP(Assumptions!$C$9/30,0)),E12*Assumptions!$C$25,0),IF(4=MAX(1,ROUNDUP(Assumptions!$C$9/30,0)),F12*Assumptions!$C$25,0),IF(3=MAX(1,ROUNDUP(Assumptions!$C$9/30,0)),G12*Assumptions!$C$25,0),IF(2=MAX(1,ROUNDUP(Assumptions!$C$9/30,0)),H12*Assumptions!$C$25,0),IF(1=MAX(1,ROUNDUP(Assumptions!$C$9/30,0)),I12*Assumptions!$C$25,0),IF(0=MAX(1,ROUNDUP(Assumptions!$C$9/30,0)),J12*Assumptions!$C$25,0)) -> 9.2215733e-07 | K19: =SUM(IF(8=MAX(1,ROUNDUP(Assumptions!$C$9/30,0)),C12*Assumptions!$C$25,0),IF(7=MAX(1,ROUNDUP(Assumptions!$C$9/30,0)),D12*Assumptions!$C$25,0),IF(6=MAX(1,ROUNDUP(Assumptions!$C$9/30,0)),E12*Assumptions!$C$25,0),IF(5=MAX(1,ROUNDUP(Assumptions!$C$9/30,0)),F12*Assumptions!$C$25,0),IF(4=MAX(1,ROUNDUP(Assumptions!$C$9/30,0)),G12*Assumptions!$C$25,0),IF(3=MAX(1,ROUNDUP(Assumptions!$C$9/30,0)),H12*Assumptions!$C$25,0),IF(2=MAX(1,ROUNDUP(Assumptions!$C$9/30,0)),I12*Assumptions!$C$25,0),IF(1=MAX(1,ROUNDUP(Assumptions!$C$9/30,0)),J12*Assumptions!$C$25,0),IF(0=MAX(1,ROUNDUP(Assumptions!$C$9/30,0)),K12*Assumptions!$C$25,0)) -> 7.7461216e-08 | L19: =SUM(IF(9=MAX(1,ROUNDUP(Assumptions!$C$9/30,0)),C12*Assumptions!$C$25,0),IF(8=MAX(1,ROUNDUP(Assumptions!$C$9/30,0)),D12*Assumptions!$C$25,0),IF(7=MAX(1,ROUNDUP(Assumptions!$C$9/30,0)),E12*Assumptions!$C$25,0),IF(6=MAX(1,ROUNDUP(Assumptions!$C$9/30,0)),F12*Assumptions!$C$25,0),IF(5=MAX(1,ROUNDUP(Assumptions!$C$9/30,0)),G12*Assumptions!$C$25,0),IF(4=MAX(1,ROUNDUP(Assumptions!$C$9/30,0)),H12*Assumptions!$C$25,0),IF(3=MAX(1,ROUNDUP(Assumptions!$C$9/30,0)),I12*Assumptions!$C$25,0),IF(2=MAX(1,ROUNDUP(Assumptions!$C$9/30,0)),J12*Assumptions!$C$25,0),IF(1=MAX(1,ROUNDUP(Assumptions!$C$9/30,0)),K12*Assumptions!$C$25,0),IF(0=MAX(1,ROUNDUP(Assumptions!$C$9/30,0)),L12*Assumptions!$C$25,0)) -> 6.5067421e-09 | M19: =SUM(IF(10=MAX(1,ROUNDUP(Assumptions!$C$9/30,0)),C12*Assumptions!$C$25,0),IF(9=MAX(1,ROUNDUP(Assumptions!$C$9/30,0)),D12*Assumptions!$C$25,0),IF(8=MAX(1,ROUNDUP(Assumptions!$C$9/30,0)),E12*Assumptions!$C$25,0),IF(7=MAX(1,ROUNDUP(Assumptions!$C$9/30,0)),F12*Assumptions!$C$25,0),IF(6=MAX(1,ROUNDUP(Assumptions!$C$9/30,0)),G12*Assumptions!$C$25,0),IF(5=MAX(1,ROUNDUP(Assumptions!$C$9/30,0)),H12*Assumptions!$C$25,0),IF(4=MAX(1,ROUNDUP(Assumptions!$C$9/30,0)),I12*Assumptions!$C$25,0),IF(3=MAX(1,ROUNDUP(Assumptions!$C$9/30,0)),J12*Assumptions!$C$25,0),IF(2=MAX(1,ROUNDUP(Assumptions!$C$9/30,0)),K12*Assumptions!$C$25,0),IF(1=MAX(1,ROUNDUP(Assumptions!$C$9/30,0)),L12*Assumptions!$C$25,0),IF(0=MAX(1,ROUNDUP(Assumptions!$C$9/30,0)),M12*Assumptions!$C$25,0)) -> 5.4656634e-10 | N19: =SUM(IF(11=MAX(1,ROUNDUP(Assumptions!$C$9/30,0)),C12*Assumptions!$C$25,0),IF(10=MAX(1,ROUNDUP(Assumptions!$C$9/30,0)),D12*Assumptions!$C$25,0),IF(9=MAX(1,ROUNDUP(Assumptions!$C$9/30,0)),E12*Assumptions!$C$25,0),IF(8=MAX(1,ROUNDUP(Assumptions!$C$9/30,0)),F12*Assumptions!$C$25,0),IF(7=MAX(1,ROUNDUP(Assumptions!$C$9/30,0)),G12*Assumptions!$C$25,0),IF(6=MAX(1,ROUNDUP(Assumptions!$C$9/30,0)),H12*Assumptions!$C$25,0),IF(5=MAX(1,ROUNDUP(Assumptions!$C$9/30,0)),I12*Assumptions!$C$25,0),IF(4=MAX(1,ROUNDUP(Assumptions!$C$9/30,0)),J12*Assumptions!$C$25,0),IF(3=MAX(1,ROUNDUP(Assumptions!$C$9/30,0)),K12*Assumptions!$C$25,0),IF(2=MAX(1,ROUNDUP(Assumptions!$C$9/30,0)),L12*Assumptions!$C$25,0),IF(1=MAX(1,ROUNDUP(Assumptions!$C$9/30,0)),M12*Assumptions!$C$25,0),IF(0=MAX(1,ROUNDUP(Assumptions!$C$9/30,0)),N12*Assumptions!$C$25,0)) -> 4.5911573e-11 | O19: =SUM(IF(12=MAX(1,ROUNDUP(Assumptions!$C$9/30,0)),C12*Assumptions!$C$25,0),IF(11=MAX(1,ROUNDUP(Assumptions!$C$9/30,0)),D12*Assumptions!$C$25,0),IF(10=MAX(1,ROUNDUP(Assumptions!$C$9/30,0)),E12*Assumptions!$C$25,0),IF(9=MAX(1,ROUNDUP(Assumptions!$C$9/30,0)),F12*Assumptions!$C$25,0),IF(8=MAX(1,ROUNDUP(Assumptions!$C$9/30,0)),G12*Assumptions!$C$25,0),IF(7=MAX(1,ROUNDUP(Assumptions!$C$9/30,0)),H12*Assumptions!$C$25,0),IF(6=MAX(1,ROUNDUP(Assumptions!$C$9/30,0)),I12*Assumptions!$C$25,0),IF(5=MAX(1,ROUNDUP(Assumptions!$C$9/30,0)),J12*Assumptions!$C$25,0),IF(4=MAX(1,ROUNDUP(Assumptions!$C$9/30,0)),K12*Assumptions!$C$25,0),IF(3=MAX(1,ROUNDUP(Assumptions!$C$9/30,0)),L12*Assumptions!$C$25,0),IF(2=MAX(1,ROUNDUP(Assumptions!$C$9/30,0)),M12*Assumptions!$C$25,0),IF(1=MAX(1,ROUNDUP(Assumptions!$C$9/30,0)),N12*Assumptions!$C$25,0),IF(0=MAX(1,ROUNDUP(Assumptions!$C$9/30,0)),O12*Assumptions!$C$25,0)) -> 3.8565721e-12 | P19: =SUM(IF(13=MAX(1,ROUNDUP(Assumptions!$C$9/30,0)),C12*Assumptions!$C$25,0),IF(12=MAX(1,ROUNDUP(Assumptions!$C$9/30,0)),D12*Assumptions!$C$25,0),IF(11=MAX(1,ROUNDUP(Assumptions!$C$9/30,0)),E12*Assumptions!$C$25,0),IF(10=MAX(1,ROUNDUP(Assumptions!$C$9/30,0)),F12*Assumptions!$C$25,0),IF(9=MAX(1,ROUNDUP(Assumptions!$C$9/30,0)),G12*Assumptions!$C$25,0),IF(8=MAX(1,ROUNDUP(Assumptions!$C$9/30,0)),H12*Assumptions!$C$25,0),IF(7=MAX(1,ROUNDUP(Assumptions!$C$9/30,0)),I12*Assumptions!$C$25,0),IF(6=MAX(1,ROUNDUP(Assumptions!$C$9/30,0)),J12*Assumptions!$C$25,0),IF(5=MAX(1,ROUNDUP(Assumptions!$C$9/30,0)),K12*Assumptions!$C$25,0),IF(4=MAX(1,ROUNDUP(Assumptions!$C$9/30,0)),L12*Assumptions!$C$25,0),IF(3=MAX(1,ROUNDUP(Assumptions!$C$9/30,0)),M12*Assumptions!$C$25,0),IF(2=MAX(1,ROUNDUP(Assumptions!$C$9/30,0)),N12*Assumptions!$C$25,0),IF(1=MAX(1,ROUNDUP(Assumptions!$C$9/30,0)),O12*Assumptions!$C$25,0),IF(0=MAX(1,ROUNDUP(Assumptions!$C$9/30,0)),P12*Assumptions!$C$25,0)) -> 3.2395206e-13 | Q19: =SUM(IF(14=MAX(1,ROUNDUP(Assumptions!$C$9/30,0)),C12*Assumptions!$C$25,0),IF(13=MAX(1,ROUNDUP(Assumptions!$C$9/30,0)),D12*Assumptions!$C$25,0),IF(12=MAX(1,ROUNDUP(Assumptions!$C$9/30,0)),E12*Assumptions!$C$25,0),IF(11=MAX(1,ROUNDUP(Assumptions!$C$9/30,0)),F12*Assumptions!$C$25,0),IF(10=MAX(1,ROUNDUP(Assumptions!$C$9/30,0)),G12*Assumptions!$C$25,0),IF(9=MAX(1,ROUNDUP(Assumptions!$C$9/30,0)),H12*Assumptions!$C$25,0),IF(8=MAX(1,ROUNDUP(Assumptions!$C$9/30,0)),I12*Assumptions!$C$25,0),IF(7=MAX(1,ROUNDUP(Assumptions!$C$9/30,0)),J12*Assumptions!$C$25,0),IF(6=MAX(1,ROUNDUP(Assumptions!$C$9/30,0)),K12*Assumptions!$C$25,0),IF(5=MAX(1,ROUNDUP(Assumptions!$C$9/30,0)),L12*Assumptions!$C$25,0),IF(4=MAX(1,ROUNDUP(Assumptions!$C$9/30,0)),M12*Assumptions!$C$25,0),IF(3=MAX(1,ROUNDUP(Assumptions!$C$9/30,0)),N12*Assumptions!$C$25,0),IF(2=MAX(1,ROUNDUP(Assumptions!$C$9/30,0)),O12*Assumptions!$C$25,0),IF(1=MAX(1,ROUNDUP(Assumptions!$C$9/30,0)),P12*Assumptions!$C$25,0),IF(0=MAX(1,ROUNDUP(Assumptions!$C$9/30,0)),Q12*Assumptions!$C$25,0)) -> 2.7211973e-14 | R19: =SUM(IF(15=MAX(1,ROUNDUP(Assumptions!$C$9/30,0)),C12*Assumptions!$C$25,0),IF(14=MAX(1,ROUNDUP(Assumptions!$C$9/30,0)),D12*Assumptions!$C$25,0),IF(13=MAX(1,ROUNDUP(Assumptions!$C$9/30,0)),E12*Assumptions!$C$25,0),IF(12=MAX(1,ROUNDUP(Assumptions!$C$9/30,0)),F12*Assumptions!$C$25,0),IF(11=MAX(1,ROUNDUP(Assumptions!$C$9/30,0)),G12*Assumptions!$C$25,0),IF(10=MAX(1,ROUNDUP(Assumptions!$C$9/30,0)),H12*Assumptions!$C$25,0),IF(9=MAX(1,ROUNDUP(Assumptions!$C$9/30,0)),I12*Assumptions!$C$25,0),IF(8=MAX(1,ROUNDUP(Assumptions!$C$9/30,0)),J12*Assumptions!$C$25,0),IF(7=MAX(1,ROUNDUP(Assumptions!$C$9/30,0)),K12*Assumptions!$C$25,0),IF(6=MAX(1,ROUNDUP(Assumptions!$C$9/30,0)),L12*Assumptions!$C$25,0),IF(5=MAX(1,ROUNDUP(Assumptions!$C$9/30,0)),M12*Assumptions!$C$25,0),IF(4=MAX(1,ROUNDUP(Assumptions!$C$9/30,0)),N12*Assumptions!$C$25,0),IF(3=MAX(1,ROUNDUP(Assumptions!$C$9/30,0)),O12*Assumptions!$C$25,0),IF(2=MAX(1,ROUNDUP(Assumptions!$C$9/30,0)),P12*Assumptions!$C$25,0),IF(1=MAX(1,ROUNDUP(Assumptions!$C$9/30,0)),Q12*Assumptions!$C$25,0),IF(0=MAX(1,ROUNDUP(Assumptions!$C$9/30,0)),R12*Assumptions!$C$25,0)) -> 2.2858057e-15 | S19: =SUM(IF(16=MAX(1,ROUNDUP(Assumptions!$C$9/30,0)),C12*Assumptions!$C$25,0),IF(15=MAX(1,ROUNDUP(Assumptions!$C$9/30,0)),D12*Assumptions!$C$25,0),IF(14=MAX(1,ROUNDUP(Assumptions!$C$9/30,0)),E12*Assumptions!$C$25,0),IF(13=MAX(1,ROUNDUP(Assumptions!$C$9/30,0)),F12*Assumptions!$C$25,0),IF(12=MAX(1,ROUNDUP(Assumptions!$C$9/30,0)),G12*Assumptions!$C$25,0),IF(11=MAX(1,ROUNDUP(Assumptions!$C$9/30,0)),H12*Assumptions!$C$25,0),IF(10=MAX(1,ROUNDUP(Assumptions!$C$9/30,0)),I12*Assumptions!$C$25,0),IF(9=MAX(1,ROUNDUP(Assumptions!$C$9/30,0)),J12*Assumptions!$C$25,0),IF(8=MAX(1,ROUNDUP(Assumptions!$C$9/30,0)),K12*Assumptions!$C$25,0),IF(7=MAX(1,ROUNDUP(Assumptions!$C$9/30,0)),L12*Assumptions!$C$25,0),IF(6=MAX(1,ROUNDUP(Assumptions!$C$9/30,0)),M12*Assumptions!$C$25,0),IF(5=MAX(1,ROUNDUP(Assumptions!$C$9/30,0)),N12*Assumptions!$C$25,0),IF(4=MAX(1,ROUNDUP(Assumptions!$C$9/30,0)),O12*Assumptions!$C$25,0),IF(3=MAX(1,ROUNDUP(Assumptions!$C$9/30,0)),P12*Assumptions!$C$25,0),IF(2=MAX(1,ROUNDUP(Assumptions!$C$9/30,0)),Q12*Assumptions!$C$25,0),IF(1=MAX(1,ROUNDUP(Assumptions!$C$9/30,0)),R12*Assumptions!$C$25,0),IF(0=MAX(1,ROUNDUP(Assumptions!$C$9/30,0)),S12*Assumptions!$C$25,0)) -> 1.9200768e-16 | T19: =SUM(IF(17=MAX(1,ROUNDUP(Assumptions!$C$9/30,0)),C12*Assumptions!$C$25,0),IF(16=MAX(1,ROUNDUP(Assumptions!$C$9/30,0)),D12*Assumptions!$C$25,0),IF(15=MAX(1,ROUNDUP(Assumptions!$C$9/30,0)),E12*Assumptions!$C$25,0),IF(14=MAX(1,ROUNDUP(Assumptions!$C$9/30,0)),F12*Assumptions!$C$25,0),IF(13=MAX(1,ROUNDUP(Assumptions!$C$9/30,0)),G12*Assumptions!$C$25,0),IF(12=MAX(1,ROUNDUP(Assumptions!$C$9/30,0)),H12*Assumptions!$C$25,0),IF(11=MAX(1,ROUNDUP(Assumptions!$C$9/30,0)),I12*Assumptions!$C$25,0),IF(10=MAX(1,ROUNDUP(Assumptions!$C$9/30,0)),J12*Assumptions!$C$25,0),IF(9=MAX(1,ROUNDUP(Assumptions!$C$9/30,0)),K12*Assumptions!$C$25,0),IF(8=MAX(1,ROUNDUP(Assumptions!$C$9/30,0)),L12*Assumptions!$C$25,0),IF(7=MAX(1,ROUNDUP(Assumptions!$C$9/30,0)),M12*Assumptions!$C$25,0),IF(6=MAX(1,ROUNDUP(Assumptions!$C$9/30,0)),N12*Assumptions!$C$25,0),IF(5=MAX(1,ROUNDUP(Assumptions!$C$9/30,0)),O12*Assumptions!$C$25,0),IF(4=MAX(1,ROUNDUP(Assumptions!$C$9/30,0)),P12*Assumptions!$C$25,0),IF(3=MAX(1,ROUNDUP(Assumptions!$C$9/30,0)),Q12*Assumptions!$C$25,0),IF(2=MAX(1,ROUNDUP(Assumptions!$C$9/30,0)),R12*Assumptions!$C$25,0),IF(1=MAX(1,ROUNDUP(Assumptions!$C$9/30,0)),S12*Assumptions!$C$25,0),IF(0=MAX(1,ROUNDUP(Assumptions!$C$9/30,0)),T12*Assumptions!$C$25,0)) -> 1.6128645e-17 | U19: =SUM(IF(18=MAX(1,ROUNDUP(Assumptions!$C$9/30,0)),C12*Assumptions!$C$25,0),IF(17=MAX(1,ROUNDUP(Assumptions!$C$9/30,0)),D12*Assumptions!$C$25,0),IF(16=MAX(1,ROUNDUP(Assumptions!$C$9/30,0)),E12*Assumptions!$C$25,0),IF(15=MAX(1,ROUNDUP(Assumptions!$C$9/30,0)),F12*Assumptions!$C$25,0),IF(14=MAX(1,ROUNDUP(Assumptions!$C$9/30,0)),G12*Assumptions!$C$25,0),IF(13=MAX(1,ROUNDUP(Assumptions!$C$9/30,0)),H12*Assumptions!$C$25,0),IF(12=MAX(1,ROUNDUP(Assumptions!$C$9/30,0)),I12*Assumptions!$C$25,0),IF(11=MAX(1,ROUNDUP(Assumptions!$C$9/30,0)),J12*Assumptions!$C$25,0),IF(10=MAX(1,ROUNDUP(Assumptions!$C$9/30,0)),K12*Assumptions!$C$25,0),IF(9=MAX(1,ROUNDUP(Assumptions!$C$9/30,0)),L12*Assumptions!$C$25,0),IF(8=MAX(1,ROUNDUP(Assumptions!$C$9/30,0)),M12*Assumptions!$C$25,0),IF(7=MAX(1,ROUNDUP(Assumptions!$C$9/30,0)),N12*Assumptions!$C$25,0),IF(6=MAX(1,ROUNDUP(Assumptions!$C$9/30,0)),O12*Assumptions!$C$25,0),IF(5=MAX(1,ROUNDUP(Assumptions!$C$9/30,0)),P12*Assumptions!$C$25,0),IF(4=MAX(1,ROUNDUP(Assumptions!$C$9/30,0)),Q12*Assumptions!$C$25,0),IF(3=MAX(1,ROUNDUP(Assumptions!$C$9/30,0)),R12*Assumptions!$C$25,0),IF(2=MAX(1,ROUNDUP(Assumptions!$C$9/30,0)),S12*Assumptions!$C$25,0),IF(1=MAX(1,ROUNDUP(Assumptions!$C$9/30,0)),T12*Assumptions!$C$25,0),IF(0=MAX(1,ROUNDUP(Assumptions!$C$9/30,0)),U12*Assumptions!$C$25,0)) -> 1.3548062e-18 | V19: =SUM(IF(19=MAX(1,ROUNDUP(Assumptions!$C$9/30,0)),C12*Assumptions!$C$25,0),IF(18=MAX(1,ROUNDUP(Assumptions!$C$9/30,0)),D12*Assumptions!$C$25,0),IF(17=MAX(1,ROUNDUP(Assumptions!$C$9/30,0)),E12*Assumptions!$C$25,0),IF(16=MAX(1,ROUNDUP(Assumptions!$C$9/30,0)),F12*Assumptions!$C$25,0),IF(15=MAX(1,ROUNDUP(Assumptions!$C$9/30,0)),G12*Assumptions!$C$25,0),IF(14=MAX(1,ROUNDUP(Assumptions!$C$9/30,0)),H12*Assumptions!$C$25,0),IF(13=MAX(1,ROUNDUP(Assumptions!$C$9/30,0)),I12*Assumptions!$C$25,0),IF(12=MAX(1,ROUNDUP(Assumptions!$C$9/30,0)),J12*Assumptions!$C$25,0),IF(11=MAX(1,ROUNDUP(Assumptions!$C$9/30,0)),K12*Assumptions!$C$25,0),IF(10=MAX(1,ROUNDUP(Assumptions!$C$9/30,0)),L12*Assumptions!$C$25,0),IF(9=MAX(1,ROUNDUP(Assumptions!$C$9/30,0)),M12*Assumptions!$C$25,0),IF(8=MAX(1,ROUNDUP(Assumptions!$C$9/30,0)),N12*Assumptions!$C$25,0),IF(7=MAX(1,ROUNDUP(Assumptions!$C$9/30,0)),O12*Assumptions!$C$25,0),IF(6=MAX(1,ROUNDUP(Assumptions!$C$9/30,0)),P12*Assumptions!$C$25,0),IF(5=MAX(1,ROUNDUP(Assumptions!$C$9/30,0)),Q12*Assumptions!$C$25,0),IF(4=MAX(1,ROUNDUP(Assumptions!$C$9/30,0)),R12*Assumptions!$C$25,0),IF(3=MAX(1,ROUNDUP(Assumptions!$C$9/30,0)),S12*Assumptions!$C$25,0),IF(2=MAX(1,ROUNDUP(Assumptions!$C$9/30,0)),T12*Assumptions!$C$25,0),IF(1=MAX(1,ROUNDUP(Assumptions!$C$9/30,0)),U12*Assumptions!$C$25,0),IF(0=MAX(1,ROUNDUP(Assumptions!$C$9/30,0)),V12*Assumptions!$C$25,0)) -> 1.1380372e-19 | W19: =SUM(IF(20=MAX(1,ROUNDUP(Assumptions!$C$9/30,0)),C12*Assumptions!$C$25,0),IF(19=MAX(1,ROUNDUP(Assumptions!$C$9/30,0)),D12*Assumptions!$C$25,0),IF(18=MAX(1,ROUNDUP(Assumptions!$C$9/30,0)),E12*Assumptions!$C$25,0),IF(17=MAX(1,ROUNDUP(Assumptions!$C$9/30,0)),F12*Assumptions!$C$25,0),IF(16=MAX(1,ROUNDUP(Assumptions!$C$9/30,0)),G12*Assumptions!$C$25,0),IF(15=MAX(1,ROUNDUP(Assumptions!$C$9/30,0)),H12*Assumptions!$C$25,0),IF(14=MAX(1,ROUNDUP(Assumptions!$C$9/30,0)),I12*Assumptions!$C$25,0),IF(13=MAX(1,ROUNDUP(Assumptions!$C$9/30,0)),J12*Assumptions!$C$25,0),IF(12=MAX(1,ROUNDUP(Assumptions!$C$9/30,0)),K12*Assumptions!$C$25,0),IF(11=MAX(1,ROUNDUP(Assumptions!$C$9/30,0)),L12*Assumptions!$C$25,0),IF(10=MAX(1,ROUNDUP(Assumptions!$C$9/30,0)),M12*Assumptions!$C$25,0),IF(9=MAX(1,ROUNDUP(Assumptions!$C$9/30,0)),N12*Assumptions!$C$25,0),IF(8=MAX(1,ROUNDUP(Assumptions!$C$9/30,0)),O12*Assumptions!$C$25,0),IF(7=MAX(1,ROUNDUP(Assumptions!$C$9/30,0)),P12*Assumptions!$C$25,0),IF(6=MAX(1,ROUNDUP(Assumptions!$C$9/30,0)),Q12*Assumptions!$C$25,0),IF(5=MAX(1,ROUNDUP(Assumptions!$C$9/30,0)),R12*Assumptions!$C$25,0),IF(4=MAX(1,ROUNDUP(Assumptions!$C$9/30,0)),S12*Assumptions!$C$25,0),IF(3=MAX(1,ROUNDUP(Assumptions!$C$9/30,0)),T12*Assumptions!$C$25,0),IF(2=MAX(1,ROUNDUP(Assumptions!$C$9/30,0)),U12*Assumptions!$C$25,0),IF(1=MAX(1,ROUNDUP(Assumptions!$C$9/30,0)),V12*Assumptions!$C$25,0),IF(0=MAX(1,ROUNDUP(Assumptions!$C$9/30,0)),W12*Assumptions!$C$25,0)) -> 9.5595124e-21 | X19: =SUM(IF(21=MAX(1,ROUNDUP(Assumptions!$C$9/30,0)),C12*Assumptions!$C$25,0),IF(20=MAX(1,ROUNDUP(Assumptions!$C$9/30,0)),D12*Assumptions!$C$25,0),IF(19=MAX(1,ROUNDUP(Assumptions!$C$9/30,0)),E12*Assumptions!$C$25,0),IF(18=MAX(1,ROUNDUP(Assumptions!$C$9/30,0)),F12*Assumptions!$C$25,0),IF(17=MAX(1,ROUNDUP(Assumptions!$C$9/30,0)),G12*Assumptions!$C$25,0),IF(16=MAX(1,ROUNDUP(Assumptions!$C$9/30,0)),H12*Assumptions!$C$25,0),IF(15=MAX(1,ROUNDUP(Assumptions!$C$9/30,0)),I12*Assumptions!$C$25,0),IF(14=MAX(1,ROUNDUP(Assumptions!$C$9/30,0)),J12*Assumptions!$C$25,0),IF(13=MAX(1,ROUNDUP(Assumptions!$C$9/30,0)),K12*Assumptions!$C$25,0),IF(12=MAX(1,ROUNDUP(Assumptions!$C$9/30,0)),L12*Assumptions!$C$25,0),IF(11=MAX(1,ROUNDUP(Assumptions!$C$9/30,0)),M12*Assumptions!$C$25,0),IF(10=MAX(1,ROUNDUP(Assumptions!$C$9/30,0)),N12*Assumptions!$C$25,0),IF(9=MAX(1,ROUNDUP(Assumptions!$C$9/30,0)),O12*Assumptions!$C$25,0),IF(8=MAX(1,ROUNDUP(Assumptions!$C$9/30,0)),P12*Assumptions!$C$25,0),IF(7=MAX(1,ROUNDUP(Assumptions!$C$9/30,0)),Q12*Assumptions!$C$25,0),IF(6=MAX(1,ROUNDUP(Assumptions!$C$9/30,0)),R12*Assumptions!$C$25,0),IF(5=MAX(1,ROUNDUP(Assumptions!$C$9/30,0)),S12*Assumptions!$C$25,0),IF(4=MAX(1,ROUNDUP(Assumptions!$C$9/30,0)),T12*Assumptions!$C$25,0),IF(3=MAX(1,ROUNDUP(Assumptions!$C$9/30,0)),U12*Assumptions!$C$25,0),IF(2=MAX(1,ROUNDUP(Assumptions!$C$9/30,0)),V12*Assumptions!$C$25,0),IF(1=MAX(1,ROUNDUP(Assumptions!$C$9/30,0)),W12*Assumptions!$C$25,0),IF(0=MAX(1,ROUNDUP(Assumptions!$C$9/30,0)),X12*Assumptions!$C$25,0)) -> 8.0299905e-22 | Y19: =SUM(IF(22=MAX(1,ROUNDUP(Assumptions!$C$9/30,0)),C12*Assumptions!$C$25,0),IF(21=MAX(1,ROUNDUP(Assumptions!$C$9/30,0)),D12*Assumptions!$C$25,0),IF(20=MAX(1,ROUNDUP(Assumptions!$C$9/30,0)),E12*Assumptions!$C$25,0),IF(19=MAX(1,ROUNDUP(Assumptions!$C$9/30,0)),F12*Assumptions!$C$25,0),IF(18=MAX(1,ROUNDUP(Assumptions!$C$9/30,0)),G12*Assumptions!$C$25,0),IF(17=MAX(1,ROUNDUP(Assumptions!$C$9/30,0)),H12*Assumptions!$C$25,0),IF(16=MAX(1,ROUNDUP(Assumptions!$C$9/30,0)),I12*Assumptions!$C$25,0),IF(15=MAX(1,ROUNDUP(Assumptions!$C$9/30,0)),J12*Assumptions!$C$25,0),IF(14=MAX(1,ROUNDUP(Assumptions!$C$9/30,0)),K12*Assumptions!$C$25,0),IF(13=MAX(1,ROUNDUP(Assumptions!$C$9/30,0)),L12*Assumptions!$C$25,0),IF(12=MAX(1,ROUNDUP(Assumptions!$C$9/30,0)),M12*Assumptions!$C$25,0),IF(11=MAX(1,ROUNDUP(Assumptions!$C$9/30,0)),N12*Assumptions!$C$25,0),IF(10=MAX(1,ROUNDUP(Assumptions!$C$9/30,0)),O12*Assumptions!$C$25,0),IF(9=MAX(1,ROUNDUP(Assumptions!$C$9/30,0)),P12*Assumptions!$C$25,0),IF(8=MAX(1,ROUNDUP(Assumptions!$C$9/30,0)),Q12*Assumptions!$C$25,0),IF(7=MAX(1,ROUNDUP(Assumptions!$C$9/30,0)),R12*Assumptions!$C$25,0),IF(6=MAX(1,ROUNDUP(Assumptions!$C$9/30,0)),S12*Assumptions!$C$25,0),IF(5=MAX(1,ROUNDUP(Assumptions!$C$9/30,0)),T12*Assumptions!$C$25,0),IF(4=MAX(1,ROUNDUP(Assumptions!$C$9/30,0)),U12*Assumptions!$C$25,0),IF(3=MAX(1,ROUNDUP(Assumptions!$C$9/30,0)),V12*Assumptions!$C$25,0),IF(2=MAX(1,ROUNDUP(Assumptions!$C$9/30,0)),W12*Assumptions!$C$25,0),IF(1=MAX(1,ROUNDUP(Assumptions!$C$9/30,0)),X12*Assumptions!$C$25,0),IF(0=MAX(1,ROUNDUP(Assumptions!$C$9/30,0)),Y12*Assumptions!$C$25,0)) -> 6.745192e-23 | Z19: =SUM(IF(23=MAX(1,ROUNDUP(Assumptions!$C$9/30,0)),C12*Assumptions!$C$25,0),IF(22=MAX(1,ROUNDUP(Assumptions!$C$9/30,0)),D12*Assumptions!$C$25,0),IF(21=MAX(1,ROUNDUP(Assumptions!$C$9/30,0)),E12*Assumptions!$C$25,0),IF(20=MAX(1,ROUNDUP(Assumptions!$C$9/30,0)),F12*Assumptions!$C$25,0),IF(19=MAX(1,ROUNDUP(Assumptions!$C$9/30,0)),G12*Assumptions!$C$25,0),IF(18=MAX(1,ROUNDUP(Assumptions!$C$9/30,0)),H12*Assumptions!$C$25,0),IF(17=MAX(1,ROUNDUP(Assumptions!$C$9/30,0)),I12*Assumptions!$C$25,0),IF(16=MAX(1,ROUNDUP(Assumptions!$C$9/30,0)),J12*Assumptions!$C$25,0),IF(15=MAX(1,ROUNDUP(Assumptions!$C$9/30,0)),K12*Assumptions!$C$25,0),IF(14=MAX(1,ROUNDUP(Assumptions!$C$9/30,0)),L12*Assumptions!$C$25,0),IF(13=MAX(1,ROUNDUP(Assumptions!$C$9/30,0)),M12*Assumptions!$C$25,0),IF(12=MAX(1,ROUNDUP(Assumptions!$C$9/30,0)),N12*Assumptions!$C$25,0),IF(11=MAX(1,ROUNDUP(Assumptions!$C$9/30,0)),O12*Assumptions!$C$25,0),IF(10=MAX(1,ROUNDUP(Assumptions!$C$9/30,0)),P12*Assumptions!$C$25,0),IF(9=MAX(1,ROUNDUP(Assumptions!$C$9/30,0)),Q12*Assumptions!$C$25,0),IF(8=MAX(1,ROUNDUP(Assumptions!$C$9/30,0)),R12*Assumptions!$C$25,0),IF(7=MAX(1,ROUNDUP(Assumptions!$C$9/30,0)),S12*Assumptions!$C$25,0),IF(6=MAX(1,ROUNDUP(Assumptions!$C$9/30,0)),T12*Assumptions!$C$25,0),IF(5=MAX(1,ROUNDUP(Assumptions!$C$9/30,0)),U12*Assumptions!$C$25,0),IF(4=MAX(1,ROUNDUP(Assumptions!$C$9/30,0)),V12*Assumptions!$C$25,0),IF(3=MAX(1,ROUNDUP(Assumptions!$C$9/30,0)),W12*Assumptions!$C$25,0),IF(2=MAX(1,ROUNDUP(Assumptions!$C$9/30,0)),X12*Assumptions!$C$25,0),IF(1=MAX(1,ROUNDUP(Assumptions!$C$9/30,0)),Y12*Assumptions!$C$25,0),IF(0=MAX(1,ROUNDUP(Assumptions!$C$9/30,0)),Z12*Assumptions!$C$25,0)) -> 5.6659613e-24
A20: 사전예약 무료월 후 유료 | B20: 명 | C20: =IF(0=Assumptions!$C$12,$C$8*Assumptions!$C$26,0) -> 0 | D20: =IF(1=Assumptions!$C$12,$C$8*Assumptions!$C$26,0) -> 4.2 | E20: =IF(2=Assumptions!$C$12,$C$8*Assumptions!$C$26,0) -> 0 | F20: =IF(3=Assumptions!$C$12,$C$8*Assumptions!$C$26,0) -> 0 | G20: =IF(4=Assumptions!$C$12,$C$8*Assumptions!$C$26,0) -> 0 | H20: =IF(5=Assumptions!$C$12,$C$8*Assumptions!$C$26,0) -> 0 | I20: =IF(6=Assumptions!$C$12,$C$8*Assumptions!$C$26,0) -> 0 | J20: =IF(7=Assumptions!$C$12,$C$8*Assumptions!$C$26,0) -> 0 | K20: =IF(8=Assumptions!$C$12,$C$8*Assumptions!$C$26,0) -> 0 | L20: =IF(9=Assumptions!$C$12,$C$8*Assumptions!$C$26,0) -> 0 | M20: =IF(10=Assumptions!$C$12,$C$8*Assumptions!$C$26,0) -> 0 | N20: =IF(11=Assumptions!$C$12,$C$8*Assumptions!$C$26,0) -> 0 | O20: =IF(12=Assumptions!$C$12,$C$8*Assumptions!$C$26,0) -> 0 | P20: =IF(13=Assumptions!$C$12,$C$8*Assumptions!$C$26,0) -> 0 | Q20: =IF(14=Assumptions!$C$12,$C$8*Assumptions!$C$26,0) -> 0 | R20: =IF(15=Assumptions!$C$12,$C$8*Assumptions!$C$26,0) -> 0 | S20: =IF(16=Assumptions!$C$12,$C$8*Assumptions!$C$26,0) -> 0 | T20: =IF(17=Assumptions!$C$12,$C$8*Assumptions!$C$26,0) -> 0 | U20: =IF(18=Assumptions!$C$12,$C$8*Assumptions!$C$26,0) -> 0 | V20: =IF(19=Assumptions!$C$12,$C$8*Assumptions!$C$26,0) -> 0 | W20: =IF(20=Assumptions!$C$12,$C$8*Assumptions!$C$26,0) -> 0 | X20: =IF(21=Assumptions!$C$12,$C$8*Assumptions!$C$26,0) -> 0 | Y20: =IF(22=Assumptions!$C$12,$C$8*Assumptions!$C$26,0) -> 0 | Z20: =IF(23=Assumptions!$C$12,$C$8*Assumptions!$C$26,0) -> 0
A21: 전체 신규 유료 | B21: 명 | C21: =SUM(C18:C20) -> 0 | D21: =SUM(D18:D20) -> 7.2 | E21: =SUM(E18:E20) -> 3.3705 | F21: =SUM(F18:F20) -> 3.326022 | G21: =SUM(G18:G20) -> 3.4744308 | H21: =SUM(H18:H20) -> 3.6466494 | I21: =SUM(I18:I20) -> 3.8288557 | J21: =SUM(J18:J20) -> 4.0202878 | ... Z21: =SUM(Z18:Z20) -> 8.7757822
A22: Essential 기초 유료 | B22: 명 | C22: =0 -> 0 | D22: =C31 -> 0 | E22: =D31 -> 2.88 | F22: =E31 -> 4.04388 | G22: =F31 -> 5.1154805 | H22: =G31 -> 6.1778621 | I22: =H31 -> 7.2411387 | J22: =I31 -> 8.3092481 | K22: =J31 -> 9.3855713 | ... Z22: =Y31 -> 28.780262
A23: 학생가 기초 유료 | B23: 명 | C23: =0 -> 0 | D23: =C32 -> 0 | E23: =D32 -> 3.24 | F23: =E32 -> 4.549365 | G23: =F32 -> 5.7549155 | H23: =G32 -> 6.9500948 | I23: =H32 -> 8.146281 | J23: =I32 -> 9.3479041 | K23: =J32 -> 10.558768 | ... Z23: =Y32 -> 32.377795
A24: Pro 기초 유료 | B24: 명 | C24: =0 -> 0 | D24: =C33 -> 0 | E24: =D33 -> 1.08 | F24: =E33 -> 1.516455 | G24: =F33 -> 1.9183052 | H24: =G33 -> 2.3166983 | I24: =H33 -> 2.715427 | J24: =I33 -> 3.115968 | K24: =J33 -> 3.5195892 | ... Z24: =Y33 -> 10.792598
A25: Essential 이탈 | B25: 명 | C25: =C22*Assumptions!$C$28 -> 0 | D25: =D22*Assumptions!$C$28 -> 0 | E25: =E22*Assumptions!$C$28 -> 0.18432 | F25: =F22*Assumptions!$C$28 -> 0.25880832 | G25: =G22*Assumptions!$C$28 -> 0.32739075 | H25: =H22*Assumptions!$C$28 -> 0.39538317 | I25: =I22*Assumptions!$C$28 -> 0.46343288 | J25: =J22*Assumptions!$C$28 -> 0.53179188 | ... Z25: =Z22*Assumptions!$C$28 -> 1.8419368
