Workbook

Sheet Overview
A2: 온라인 강의 요약 서비스 · 24개월 사업모델
A4: 노란 셀을 바꾸면 월별 전망과 아래 차트가 함께 갱신됩니다. 숫자는 실측 매출이 아닌 계획 시나리오입니다.
A6: 지표 | B6: M6 | C6: M12 | D6: M24
A7: 월 신규 가입 | B7: ='Monthly Model'!H14 -> 25.525631 | C7: ='Monthly Model'!N14 -> 34.206787 | D7: ='Monthly Model'!Z14 -> 61.430475
A8: 기말 유료 고객 | B8: ='Monthly Model'!H34 -> 20.97794 | C8: ='Monthly Model'!N34 -> 37.651698 | D8: ='Monthly Model'!Z34 -> 80.526663
A9: 월 순매출 (VAT 제외) | B9: ='Monthly Model'!H52 -> 385898.74 | C9: ='Monthly Model'!N52 -> 692620.1 | D9: ='Monthly Model'!Z52 -> 1481324.6
A10: 월 전체 비용 | B10: ='Monthly Model'!H74 -> 257595.14 | C10: ='Monthly Model'!N74 -> 278737.61 | D10: ='Monthly Model'!Z74 -> 333646.04
A11: 월 순이익 | B11: ='Monthly Model'!H80 -> 127796.26 | C11: ='Monthly Model'!N80 -> 372494.25 | D11: ='Monthly Model'!Z80 -> 1032910.7
A12: 누적 순이익 | B12: ='Monthly Model'!H81 -> 4566.0496 | C12: ='Monthly Model'!N81 -> 1584514 | D12: ='Monthly Model'!Z81 -> 10076368
A13: 추천 신규 가입 | B13: ='Monthly Model'!H11 -> 0 | C13: ='Monthly Model'!N11 -> 0 | D13: ='Monthly Model'!Z11 -> 0
A16: 기간 합계 | B16: 1~12개월 | C16: 13~24개월 | D16: 24개월 합계
A17: 신규 가입 | B17: =SUM('Monthly Model'!C14:N14) -> 334.70837 | C17: =SUM('Monthly Model'!O14:Z14) -> 571.69745 | D17: =B17+C17 -> 906.40582
A18: 순매출 | B18: =SUM('Monthly Model'!C52:N52) -> 4870172.1 | C18: =SUM('Monthly Model'!O52:Z52) -> 13113559 | D18: =B18+C18 -> 17983731
A19: 전체 비용 | B19: =SUM('Monthly Model'!C74:N74) -> 3109601 | C19: =SUM('Monthly Model'!O74:Z74) -> 3678166 | D19: =B19+C19 -> 6787767
A20: 순이익 | B20: =SUM('Monthly Model'!C80:N80) -> 1584514 | C20: =SUM('Monthly Model'!O80:Z80) -> 8491853.8 | D20: =B20+C20 -> 10076368
A21: 추천 가입 | B21: =SUM('Monthly Model'!C11:N11) -> 1.36584 | C21: =SUM('Monthly Model'!O11:Z11) -> 0 | D21: =B21+C21 -> 1.36584
A22: 추천 무료월 획득 | B22: =SUM('Monthly Model'!C43:N43) -> 0.10038924 | C22: =SUM('Monthly Model'!O43:Z43) -> 0 | D22: =B22+C22 -> 0.10038924
A23: 월별 매출 · 비용 · 순이익 (원) | F23: 모델 적용 규칙
A24: 월 | B24: 순매출 | C24: 전체 비용 | D24: 순이익
A25: M1 | B25: ='Monthly Model'!C52 -> 55186.364 | C25: ='Monthly Model'!C74 -> 237720.66 | D25: ='Monthly Model'!C80 -> -182534.3 | F25: 일반 무료체험 폐지. 피추천인만 Essential/EDU 14일·200분 체험.
A26: M2 | B26: ='Monthly Model'!D52 -> 189724.7 | C26: ='Monthly Model'!D74 -> 243534.36 | D26: ='Monthly Model'!D80 -> -53809.656 | F26: 일반 가입은 당월 직접 결제. 전환율 15%는 임시 비교값(C102).
A27: M3 | B27: ='Monthly Model'!E52 -> 239782.04 | C27: ='Monthly Model'!E74 -> 247212.84 | D27: ='Monthly Model'!E80 -> -7430.799 | F27: 추천 캠페인은 M1~M2만 운영합니다. 이후 신규 추천 가입은 0입니다.
A28: M4 | B28: ='Monthly Model'!F52 -> 288414.86 | C28: ='Monthly Model'!F74 -> 250729.12 | D28: ='Monthly Model'!F80 -> 37685.745 | F28: 두 명의 카드 체험으로 얻은 무료월은 다음 달 사용하고, 미사용분은 만료로 근사합니다.
A29: M5 | B29: ='Monthly Model'!G52 -> 337035.68 | C29: ='Monthly Model'!G74 -> 254176.88 | D29: ='Monthly Model'!G80 -> 82858.803 | F29: 현재 직원이 없으므로 인건비는 0원입니다. 채용 시 해당 레버를 변경하세요.
A30: M6 | B30: ='Monthly Model'!H52 -> 385898.74 | C30: ='Monthly Model'!H74 -> 257595.14 | D30: ='Monthly Model'!H80 -> 127796.26 | F30: Vercel Hobby는 비상업용만 허용되어 유료 서비스는 Pro부터 시작합니다.
A31: M7 | B31: ='Monthly Model'!I52 -> 435156.22 | C31: ='Monthly Model'!I74 -> 261011.54 | D31: ='Monthly Model'!I80 -> 156730.22 | F31: 월 이용 한도: Essential/EDU 400분, Pro 600분. 평균 사용량과 별도.
A32: M8 | B32: ='Monthly Model'!J52 -> 484958.98 | C32: ='Monthly Model'!J74 -> 264448.37 | D32: ='Monthly Model'!J80 -> 198459.55 | F32: 음성 인식은 기기 내 처리. 외부 AI 요약은 텍스트 토큰 비용만 포함합니다.
A33: M9 | B33: ='Monthly Model'!K52 -> 535457 | C33: ='Monthly Model'!K74 -> 267924.21 | D33: ='Monthly Model'!K80 -> 240779.51 | F33: 매출은 VAT 제외. 법인세는 월간 추정과 이월결손금 단순 적용입니다.
A34: M10 | B34: ='Monthly Model'!L52 -> 586799.91 | C34: ='Monthly Model'!L74 -> 271455.07 | D34: ='Monthly Model'!L80 -> 283810.36
A35: M11 | B35: ='Monthly Model'!M52 -> 639137.49 | C35: ='Monthly Model'!M74 -> 275055.18 | D35: ='Monthly Model'!M80 -> 327674.07
A36: M12 | B36: ='Monthly Model'!N52 -> 692620.1 | C36: ='Monthly Model'!N74 -> 278737.61 | D36: ='Monthly Model'!N80 -> 372494.25
A37: M13 | B37: ='Monthly Model'!O52 -> 747399.19 | C37: ='Monthly Model'!O74 -> 282514.6 | D37: ='Monthly Model'!O80 -> 418396.13
A38: M14 | B38: ='Monthly Model'!P52 -> 803627.76 | C38: ='Monthly Model'!P74 -> 286397.98 | D38: ='Monthly Model'!P80 -> 465506.81
A39: M15 | B39: ='Monthly Model'!Q52 -> 861460.81 | C39: ='Monthly Model'!Q74 -> 290399.25 | D39: ='Monthly Model'!Q80 -> 513955.41
A40: M16 | B40: ='Monthly Model'!R52 -> 921055.81 | C40: ='Monthly Model'!R74 -> 294529.85 | D40: ='Monthly Model'!R80 -> 563873.36
A41: M17 | B41: ='Monthly Model'!S52 -> 982573.15 | C41: ='Monthly Model'!S74 -> 298801.24 | D41: ='Monthly Model'!S80 -> 615394.72
A42: M18 | B42: ='Monthly Model'!T52 -> 1046176.6 | C42: ='Monthly Model'!T74 -> 303224.97 | D42: ='Monthly Model'!T80 -> 668656.48
A43: M19 | B43: ='Monthly Model'!U52 -> 1112033.9 | C43: ='Monthly Model'!U74 -> 307812.82 | D43: ='Monthly Model'!U80 -> 723798.96
A44: M20 | B44: ='Monthly Model'!V52 -> 1180316.9 | C44: ='Monthly Model'!V74 -> 312576.79 | D44: ='Monthly Model'!V80 -> 780966.11
A45: M21 | B45: ='Monthly Model'!W52 -> 1251202.5 | C45: ='Monthly Model'!W74 -> 317529.2 | D45: ='Monthly Model'!W80 -> 840305.95
...

Sheet Assumptions
A2: 사업모델 가정과 조절값
A4: 조절 항목 | B4: 단위 | C4: 값 | D4: 근거 구분 | E4: 출처 ID | F4: 정의 / 바꿀 때 확인할 점 | G4: 출시 후 1개월 | H4: 출시 후 2개월 | I4: 출시 후 3개월 | J4: 출시 후 4개월 | K4: 출시 후 5개월 | L4: 출시 후 6개월 | M4: 출시 후 7개월 | N4: 출시 후 8개월 | O4: 출시 후 9개월 | P4: 출시 후 10개월 | Q4: 출시 후 11개월 | R4: 출시 후 12개월
A5: 상품 · 체험 · 추천 규칙 | G5: 오가닉 계절 계수
A6: Essential 월 가격 | B6: 원 | C6: 24000 | D6: 사용자 | E6: U | F6: 부가세 포함 소비자 표시가 | G6: 1 | H6: 1 | I6: 1 | J6: 1 | K6: 1 | L6: 1 | M6: 1 | N6: 1 | O6: 1 | P6: 1 | Q6: 1 | R6: 1
A7: Essential 학생가 | B7: 원 | C7: 14000 | D7: 사용자 | E7: U | F7: 학생 인증 시 같은 기능
A8: Pro 월 가격 | B8: 원 | C8: 28900 | D8: 사용자 | E8: U | F8: 부가세 포함 소비자 표시가 | G8: 2년차에도 같은 계수를 반복합니다. 방학·개강 효과는 실측 후 입력하세요.
A9: 피추천인 전용 체험 기간 | B9: 일 | C9: 14 | D9: 사용자 | E9: U | F9: 일반 체험 없음. 추천 코드·카드 등록 후 14일; 다음 달 유료 전환 근사
A10: 피추천인 체험 최대 이용량 | B10: 분 | C10: 200 | D10: 사용자 | E10: U | F10: 14일 체험 전체 누적 200분; 월 한도가 아님 | G10: 가격 비중 합계 | H10: =SUM(C33,C34,C35) -> 1
A11: 1인당 초대 코드 | B11: 개 | C11: 2 | D11: 사용자 | E11: U | F11: 추천 보상은 두 코드가 모두 인정될 때 지급
A12: 사전예약 첫달 무료 | B12: 개월 | C12: 1 | D12: 사용자 | E12: U | F12: 카드 등록을 완료한 유료 플랜 이용자
A13: 추천 보상 무료 기간 | B13: 개월 | C13: 1 | D13: 사용자 | E13: U | F13: 한 추천인이 코드 2개 모두 달성 시 1회 지급
A14: 신규 유입 · 무료체험 전환
A15: 출시 시 사전예약자 | B15: 명 | C15: 25 | D15: 가정 | E15: A | F15: 현재 웨이트리스트 실측값으로 교체
A16: 사전예약 → 계정 가입 | B16: % | C16: 0.6 | D16: 가정 | E16: A | F16: 사전예약자 중 출시 후 가입 비중
A17: 사전예약 가입 → 카드 등록 | B17: % | C17: 0.7 | D17: 가정 | E17: A | F17: 첫달 무료 혜택 시작 비중
A18: 출시 첫달 오가닉 가입 | B18: 명 | C18: 20 | D18: 가정 | E18: A | F18: 광고·추천 제외. 실측 획득 채널로 교체
A19: 오가닉 월 성장률 | B19: % | C19: 0.05 | D19: 가정 | E19: A | F19: 아래 학사시즌 계수와 별도 적용
A20: 이전 오가닉 카드 체험률 (미사용) | B20: % | C20: 0.6 | D20: 가정 | E20: B1 | F20: 기존 60% 보존. 일반 체험 폐지로 계산에 미사용
A21: 추천 자격자 중 두 코드 공유 | B21: % | C21: 0.2 | D21: 참고 기반 가정 | E21: B3 | F21: 추천으로 유입된 고객의 공유율 참고. 본 제품 실측 아님
A22: 초대 코드 수신 → 가입 | B22: % | C22: 0.3 | D22: 참고 기반 가정 | E22: B3 | F22: 공유한 각 코드의 가입 확률
A23: 추천 가입 → 카드 체험 | B23: % | C23: 0.7 | D23: 가정 | E23: A | F23: 카드 등록 후 무료체험 시작이 추천 인정 조건
A24: 이전 오가닉 체험 유료율 (미사용) | B24: % | C24: 0.25 | D24: 가정 | E24: B1 | F24: 기존 25% 보존. 신규 직접 결제 전환율은 C102
A25: 추천 카드 체험 → 유료 | B25: % | C25: 0.25 | D25: 가정 | E25: B1 | F25: 체험 완료 다음 달부터 유료 과금
A26: 사전예약 첫달 무료 → 유료 | B26: % | C26: 0.4 | D26: 가정 | E26: A | F26: 무료 한 달 후 첫 결제 성공률
A27: 기존 고객 유지 · 가격 구성
A28: Essential 월 유료 이탈률 | B28: % | C28: 0.064 | D28: 벤치마크 | E28: B2 | F28: 저가 SaaS의 월 고객 이탈률 6.1~6.4% 참고
A29: 학생가 월 유료 이탈률 | B29: % | C29: 0.064 | D29: 벤치마크 | E29: B2 | F29: 방학 영향 미반영. 학사시즌 계수 조정 권장
A30: Pro 월 유료 이탈률 | B30: % | C30: 0.064 | D30: 벤치마크 | E30: B2 | F30: 계약/실측 전까지 동일 기본값
A31: Free 월 비활성 이탈률 | B31: % | C31: 0.3 | D31: 가정 | E31: A | F31: Free 계정 활성 사용자 재고의 이탈
A32: 유료 이탈 → Free 잔류 | B32: % | C32: 0.3 | D32: 가정 | E32: A | F32: 유료 해지 후 무료 사용자는 Free 재고로 이동
A33: 신규 유료 Essential 비중 | B33: % | C33: 0.4 | D33: 가정 | E33: A | F33: 학생가·Pro 비중과 합계 100%
A34: 신규 유료 학생가 비중 | B34: % | C34: 0.45 | D34: 가정 | E34: A | F34: 학생 타깃 특성 반영한 초기 가정
A35: 신규 유료 Pro 비중 | B35: % | C35: 0.15 | D35: 가정 | E35: A | F35: 나머지와 합계 100%
A36: 다음달 추천 보상 사용률 | B36: % | C36: 0.7 | D36: 가정 | E36: A | F36: 미사용분은 만료. 유료 구독 지속 여부 근사
A37: 활동량 · 추론 비용
A38: Essential 유료 월 평균 강의 | B38: 분 | C38: 200 | D38: 가정 | E38: A | F38: 평균 사용량 유지. 비용 산식에 Essential 월 한도 C100 적용
A39: 학생가 유료 월 평균 강의 | B39: 분 | C39: 200 | D39: 가정 | E39: A | F39: 평균 사용량 유지. EDU는 Essential과 동일한 월 한도
A40: Pro 유료 월 평균 강의 | B40: 분 | C40: 400 | D40: 가정 | E40: A | F40: 평균 사용량 유지. 비용 산식에 Pro 월 한도 C101 적용
A41: 피추천인 체험 평균 강의 | B41: 분 | C41: 80 | D41: 가정 | E41: A | F41: 평균 80분 가정. 체험 전체 상한 C10=200분
A42: 사전예약 무료월 평균 강의 | B42: 분 | C42: 200 | D42: 가정 | E42: A | F42: 평균 사용량 유지. 요금제 구성별 월 한도 적용
...

Sheet Monthly Model
A2: 24개월 월별 가입 · 매출 · 손익
A4: 지표 | B4: 단위 | C4: M1 | D4: M2 | E4: M3 | F4: M4 | G4: M5 | H4: M6 | I4: M7 | J4: M8 | K4: M9 | L4: M10 | M4: M11 | N4: M12 | O4: M13 | P4: M14 | Q4: M15 | R4: M16 | S4: M17 | T4: M18 | U4: M19 | V4: M20 | W4: M21 | X4: M22 | Y4: M23 | Z4: M24
A5: 유입 · 카드 등록
A6: 출시 시 사전예약 명단 | B6: 명 | C6: =Assumptions!$C$15 -> 25 | D6: =0 -> 0 | E6: =0 -> 0 | F6: =0 -> 0 | G6: =0 -> 0 | H6: =0 -> 0 | I6: =0 -> 0 | J6: =0 -> 0 | K6: =0 -> 0 | ... Z6: =0 -> 0
A7: 사전예약 → 실제 가입 | B7: 명 | C7: =C6*Assumptions!$C$16 -> 15 | D7: =D6*Assumptions!$C$16 -> 0 | E7: =E6*Assumptions!$C$16 -> 0 | F7: =F6*Assumptions!$C$16 -> 0 | G7: =G6*Assumptions!$C$16 -> 0 | H7: =H6*Assumptions!$C$16 -> 0 | I7: =I6*Assumptions!$C$16 -> 0 | J7: =J6*Assumptions!$C$16 -> 0 | ... Z7: =Z6*Assumptions!$C$16 -> 0
A8: 사전예약 카드 등록 · 첫달 무료 | B8: 명 | C8: =C7*Assumptions!$C$17 -> 10.5 | D8: =D7*Assumptions!$C$17 -> 0 | E8: =E7*Assumptions!$C$17 -> 0 | F8: =F7*Assumptions!$C$17 -> 0 | G8: =G7*Assumptions!$C$17 -> 0 | H8: =H7*Assumptions!$C$17 -> 0 | I8: =I7*Assumptions!$C$17 -> 0 | J8: =J7*Assumptions!$C$17 -> 0 | ... Z8: =Z7*Assumptions!$C$17 -> 0
A9: 오가닉 신규 가입 | B9: 명 | C9: =Assumptions!$C$18*(1+Assumptions!$C$19)^0*Assumptions!$G$6 -> 20 | D9: =Assumptions!$C$18*(1+Assumptions!$C$19)^1*Assumptions!$H$6 -> 21 | E9: =Assumptions!$C$18*(1+Assumptions!$C$19)^2*Assumptions!$I$6 -> 22.05 | F9: =Assumptions!$C$18*(1+Assumptions!$C$19)^3*Assumptions!$J$6 -> 23.1525 | G9: =Assumptions!$C$18*(1+Assumptions!$C$19)^4*Assumptions!$K$6 -> 24.310125 | H9: =Assumptions!$C$18*(1+Assumptions!$C$19)^5*Assumptions!$L$6 -> 25.525631 | I9: =Assumptions!$C$18*(1+Assumptions!$C$19)^6*Assumptions!$M$6 -> 26.801913 | J9: =Assumptions!$C$18*(1+Assumptions!$C$19)^7*Assumptions!$N$6 -> 28.142008 | K9: =Assumptions!$C$18*(1+Assumptions!$C$19)^8*Assumptions!$O$6 -> 29.549109 | L9: =Assumptions!$C$18*(1+Assumptions!$C$19)^9*Assumptions!$P$6 -> 31.026564 | M9: =Assumptions!$C$18*(1+Assumptions!$C$19)^10*Assumptions!$Q$6 -> 32.577893 | N9: =Assumptions!$C$18*(1+Assumptions!$C$19)^11*Assumptions!$R$6 -> 34.206787 | O9: =Assumptions!$C$18*(1+Assumptions!$C$19)^12*Assumptions!$G$6 -> 35.917127 | P9: =Assumptions!$C$18*(1+Assumptions!$C$19)^13*Assumptions!$H$6 -> 37.712983 | Q9: =Assumptions!$C$18*(1+Assumptions!$C$19)^14*Assumptions!$I$6 -> 39.598632 | R9: =Assumptions!$C$18*(1+Assumptions!$C$19)^15*Assumptions!$J$6 -> 41.578564 | S9: =Assumptions!$C$18*(1+Assumptions!$C$19)^16*Assumptions!$K$6 -> 43.657492 | T9: =Assumptions!$C$18*(1+Assumptions!$C$19)^17*Assumptions!$L$6 -> 45.840366 | U9: =Assumptions!$C$18*(1+Assumptions!$C$19)^18*Assumptions!$M$6 -> 48.132385 | V9: =Assumptions!$C$18*(1+Assumptions!$C$19)^19*Assumptions!$N$6 -> 50.539004 | W9: =Assumptions!$C$18*(1+Assumptions!$C$19)^20*Assumptions!$O$6 -> 53.065954 | X9: =Assumptions!$C$18*(1+Assumptions!$C$19)^21*Assumptions!$P$6 -> 55.719252 | Y9: =Assumptions!$C$18*(1+Assumptions!$C$19)^22*Assumptions!$Q$6 -> 58.505214 | Z9: =Assumptions!$C$18*(1+Assumptions!$C$19)^23*Assumptions!$R$6 -> 61.430475
A10: 추천 코드 2개 공유자 | B10: 명 | C10: =IF(1<=Assumptions!$C$74,C8*Assumptions!$C$21,0) -> 2.1 | D10: =IF(2<=Assumptions!$C$74,C12*Assumptions!$C$21,0) -> 0.1764 | E10: =IF(3<=Assumptions!$C$74,D12*Assumptions!$C$21,0) -> 0 | F10: =IF(4<=Assumptions!$C$74,E12*Assumptions!$C$21,0) -> 0 | G10: =IF(5<=Assumptions!$C$74,F12*Assumptions!$C$21,0) -> 0 | H10: =IF(6<=Assumptions!$C$74,G12*Assumptions!$C$21,0) -> 0 | I10: =IF(7<=Assumptions!$C$74,H12*Assumptions!$C$21,0) -> 0 | J10: =IF(8<=Assumptions!$C$74,I12*Assumptions!$C$21,0) -> 0 | K10: =IF(9<=Assumptions!$C$74,J12*Assumptions!$C$21,0) -> 0 | L10: =IF(10<=Assumptions!$C$74,K12*Assumptions!$C$21,0) -> 0 | M10: =IF(11<=Assumptions!$C$74,L12*Assumptions!$C$21,0) -> 0 | N10: =IF(12<=Assumptions!$C$74,M12*Assumptions!$C$21,0) -> 0 | O10: =IF(13<=Assumptions!$C$74,N12*Assumptions!$C$21,0) -> 0 | P10: =IF(14<=Assumptions!$C$74,O12*Assumptions!$C$21,0) -> 0 | Q10: =IF(15<=Assumptions!$C$74,P12*Assumptions!$C$21,0) -> 0 | R10: =IF(16<=Assumptions!$C$74,Q12*Assumptions!$C$21,0) -> 0 | S10: =IF(17<=Assumptions!$C$74,R12*Assumptions!$C$21,0) -> 0 | T10: =IF(18<=Assumptions!$C$74,S12*Assumptions!$C$21,0) -> 0 | U10: =IF(19<=Assumptions!$C$74,T12*Assumptions!$C$21,0) -> 0 | V10: =IF(20<=Assumptions!$C$74,U12*Assumptions!$C$21,0) -> 0 | W10: =IF(21<=Assumptions!$C$74,V12*Assumptions!$C$21,0) -> 0 | X10: =IF(22<=Assumptions!$C$74,W12*Assumptions!$C$21,0) -> 0 | Y10: =IF(23<=Assumptions!$C$74,X12*Assumptions!$C$21,0) -> 0 | Z10: =IF(24<=Assumptions!$C$74,Y12*Assumptions!$C$21,0) -> 0
A11: 추천 코드 신규 가입 | B11: 명 | C11: =C10*Assumptions!$C$11*Assumptions!$C$22 -> 1.26 | D11: =D10*Assumptions!$C$11*Assumptions!$C$22 -> 0.10584 | E11: =E10*Assumptions!$C$11*Assumptions!$C$22 -> 0 | F11: =F10*Assumptions!$C$11*Assumptions!$C$22 -> 0 | G11: =G10*Assumptions!$C$11*Assumptions!$C$22 -> 0 | H11: =H10*Assumptions!$C$11*Assumptions!$C$22 -> 0 | I11: =I10*Assumptions!$C$11*Assumptions!$C$22 -> 0 | J11: =J10*Assumptions!$C$11*Assumptions!$C$22 -> 0 | ... Z11: =Z10*Assumptions!$C$11*Assumptions!$C$22 -> 0
A12: 추천 카드 등록 체험 | B12: 명 | C12: =C11*Assumptions!$C$23 -> 0.882 | D12: =D11*Assumptions!$C$23 -> 0.074088 | E12: =E11*Assumptions!$C$23 -> 0 | F12: =F11*Assumptions!$C$23 -> 0 | G12: =G11*Assumptions!$C$23 -> 0 | H12: =H11*Assumptions!$C$23 -> 0 | I12: =I11*Assumptions!$C$23 -> 0 | J12: =J11*Assumptions!$C$23 -> 0 | ... Z12: =Z11*Assumptions!$C$23 -> 0
A13: 일반 가입 직접 결제 | B13: 명 | C13: =C9*Assumptions!$C$102 -> 3 | D13: =D9*Assumptions!$C$102 -> 3.15 | E13: =E9*Assumptions!$C$102 -> 3.3075 | F13: =F9*Assumptions!$C$102 -> 3.472875 | G13: =G9*Assumptions!$C$102 -> 3.6465187 | H13: =H9*Assumptions!$C$102 -> 3.8288447 | I13: =I9*Assumptions!$C$102 -> 4.0202869 | J13: =J9*Assumptions!$C$102 -> 4.2213013 | ... Z13: =Z9*Assumptions!$C$102 -> 9.2145713
A14: 전체 신규 가입 | B14: 명 | C14: =SUM(C7,C9,C11) -> 36.26 | D14: =SUM(D7,D9,D11) -> 21.10584 | E14: =SUM(E7,E9,E11) -> 22.05 | F14: =SUM(F7,F9,F11) -> 23.1525 | G14: =SUM(G7,G9,G11) -> 24.310125 | H14: =SUM(H7,H9,H11) -> 25.525631 | I14: =SUM(I7,I9,I11) -> 26.801913 | J14: =SUM(J7,J9,J11) -> 28.142008 | ... Z14: =SUM(Z7,Z9,Z11) -> 61.430475
A15: 신규 카드 등록 | B15: 명 | C15: =SUM(C8,C13,C12) -> 14.382 | D15: =SUM(D8,D13,D12) -> 3.224088 | E15: =SUM(E8,E13,E12) -> 3.3075 | F15: =SUM(F8,F13,F12) -> 3.472875 | G15: =SUM(G8,G13,G12) -> 3.6465187 | H15: =SUM(H8,H13,H12) -> 3.8288447 | I15: =SUM(I8,I13,I12) -> 4.0202869 | J15: =SUM(J8,J13,J12) -> 4.2213013 | ... Z15: =SUM(Z8,Z13,Z12) -> 9.2145713
A17: 가입 전환 · 고객 유지
A18: 일반 가입 당월 신규 유료 | B18: 명 | C18: =C13 -> 3 | D18: =D13 -> 3.15 | E18: =E13 -> 3.3075 | F18: =F13 -> 3.472875 | G18: =G13 -> 3.6465187 | H18: =H13 -> 3.8288447 | I18: =I13 -> 4.0202869 | J18: =J13 -> 4.2213013 | ... Z18: =Z13 -> 9.2145713
A19: 추천 신규 유료 | B19: 명 | C19: =SUM(IF(0=MAX(1,ROUNDUP(Assumptions!$C$9/30,0)),C12*Assumptions!$C$25,0)) -> 0 | D19: =SUM(IF(1=MAX(1,ROUNDUP(Assumptions!$C$9/30,0)),C12*Assumptions!$C$25,0),IF(0=MAX(1,ROUNDUP(Assumptions!$C$9/30,0)),D12*Assumptions!$C$25,0)) -> 0.2205 | E19: =SUM(IF(2=MAX(1,ROUNDUP(Assumptions!$C$9/30,0)),C12*Assumptions!$C$25,0),IF(1=MAX(1,ROUNDUP(Assumptions!$C$9/30,0)),D12*Assumptions!$C$25,0),IF(0=MAX(1,ROUNDUP(Assumptions!$C$9/30,0)),E12*Assumptions!$C$25,0)) -> 0.018522 | F19: =SUM(IF(3=MAX(1,ROUNDUP(Assumptions!$C$9/30,0)),C12*Assumptions!$C$25,0),IF(2=MAX(1,ROUNDUP(Assumptions!$C$9/30,0)),D12*Assumptions!$C$25,0),IF(1=MAX(1,ROUNDUP(Assumptions!$C$9/30,0)),E12*Assumptions!$C$25,0),IF(0=MAX(1,ROUNDUP(Assumptions!$C$9/30,0)),F12*Assumptions!$C$25,0)) -> 0 | G19: =SUM(IF(4=MAX(1,ROUNDUP(Assumptions!$C$9/30,0)),C12*Assumptions!$C$25,0),IF(3=MAX(1,ROUNDUP(Assumptions!$C$9/30,0)),D12*Assumptions!$C$25,0),IF(2=MAX(1,ROUNDUP(Assumptions!$C$9/30,0)),E12*Assumptions!$C$25,0),IF(1=MAX(1,ROUNDUP(Assumptions!$C$9/30,0)),F12*Assumptions!$C$25,0),IF(0=MAX(1,ROUNDUP(Assumptions!$C$9/30,0)),G12*Assumptions!$C$25,0)) -> 0 | H19: =SUM(IF(5=MAX(1,ROUNDUP(Assumptions!$C$9/30,0)),C12*Assumptions!$C$25,0),IF(4=MAX(1,ROUNDUP(Assumptions!$C$9/30,0)),D12*Assumptions!$C$25,0),IF(3=MAX(1,ROUNDUP(Assumptions!$C$9/30,0)),E12*Assumptions!$C$25,0),IF(2=MAX(1,ROUNDUP(Assumptions!$C$9/30,0)),F12*Assumptions!$C$25,0),IF(1=MAX(1,ROUNDUP(Assumptions!$C$9/30,0)),G12*Assumptions!$C$25,0),IF(0=MAX(1,ROUNDUP(Assumptions!$C$9/30,0)),H12*Assumptions!$C$25,0)) -> 0 | I19: =SUM(IF(6=MAX(1,ROUNDUP(Assumptions!$C$9/30,0)),C12*Assumptions!$C$25,0),IF(5=MAX(1,ROUNDUP(Assumptions!$C$9/30,0)),D12*Assumptions!$C$25,0),IF(4=MAX(1,ROUNDUP(Assumptions!$C$9/30,0)),E12*Assumptions!$C$25,0),IF(3=MAX(1,ROUNDUP(Assumptions!$C$9/30,0)),F12*Assumptions!$C$25,0),IF(2=MAX(1,ROUNDUP(Assumptions!$C$9/30,0)),G12*Assumptions!$C$25,0),IF(1=MAX(1,ROUNDUP(Assumptions!$C$9/30,0)),H12*Assumptions!$C$25,0),IF(0=MAX(1,ROUNDUP(Assumptions!$C$9/30,0)),I12*Assumptions!$C$25,0)) -> 0 | J19: =SUM(IF(7=MAX(1,ROUNDUP(Assumptions!$C$9/30,0)),C12*Assumptions!$C$25,0),IF(6=MAX(1,ROUNDUP(Assumptions!$C$9/30,0)),D12*Assumptions!$C$25,0),IF(5=MAX(1,ROUNDUP(Assumptions!$C$9/30,0)),E12*Assumptions!$C$25,0),IF(4=MAX(1,ROUNDUP(Assumptions!$C$9/30,0)),F12*Assumptions!$C$25,0),IF(3=MAX(1,ROUNDUP(Assumptions!$C$9/30,0)),G12*Assumptions!$C$25,0),IF(2=MAX(1,ROUNDUP(Assumptions!$C$9/30,0)),H12*Assumptions!$C$25,0),IF(1=MAX(1,ROUNDUP(Assumptions!$C$9/30,0)),I12*Assumptions!$C$25,0),IF(0=MAX(1,ROUNDUP(Assumptions!$C$9/30,0)),J12*Assumptions!$C$25,0)) -> 0 | K19: =SUM(IF(8=MAX(1,ROUNDUP(Assumptions!$C$9/30,0)),C12*Assumptions!$C$25,0),IF(7=MAX(1,ROUNDUP(Assumptions!$C$9/30,0)),D12*Assumptions!$C$25,0),IF(6=MAX(1,ROUNDUP(Assumptions!$C$9/30,0)),E12*Assumptions!$C$25,0),IF(5=MAX(1,ROUNDUP(Assumptions!$C$9/30,0)),F12*Assumptions!$C$25,0),IF(4=MAX(1,ROUNDUP(Assumptions!$C$9/30,0)),G12*Assumptions!$C$25,0),IF(3=MAX(1,ROUNDUP(Assumptions!$C$9/30,0)),H12*Assumptions!$C$25,0),IF(2=MAX(1,ROUNDUP(Assumptions!$C$9/30,0)),I12*Assumptions!$C$25,0),IF(1=MAX(1,ROUNDUP(Assumptions!$C$9/30,0)),J12*Assumptions!$C$25,0),IF(0=MAX(1,ROUNDUP(Assumptions!$C$9/30,0)),K12*Assumptions!$C$25,0)) -> 0 | L19: =SUM(IF(9=MAX(1,ROUNDUP(Assumptions!$C$9/30,0)),C12*Assumptions!$C$25,0),IF(8=MAX(1,ROUNDUP(Assumptions!$C$9/30,0)),D12*Assumptions!$C$25,0),IF(7=MAX(1,ROUNDUP(Assumptions!$C$9/30,0)),E12*Assumptions!$C$25,0),IF(6=MAX(1,ROUNDUP(Assumptions!$C$9/30,0)),F12*Assumptions!$C$25,0),IF(5=MAX(1,ROUNDUP(Assumptions!$C$9/30,0)),G12*Assumptions!$C$25,0),IF(4=MAX(1,ROUNDUP(Assumptions!$C$9/30,0)),H12*Assumptions!$C$25,0),IF(3=MAX(1,ROUNDUP(Assumptions!$C$9/30,0)),I12*Assumptions!$C$25,0),IF(2=MAX(1,ROUNDUP(Assumptions!$C$9/30,0)),J12*Assumptions!$C$25,0),IF(1=MAX(1,ROUNDUP(Assumptions!$C$9/30,0)),K12*Assumptions!$C$25,0),IF(0=MAX(1,ROUNDUP(Assumptions!$C$9/30,0)),L12*Assumptions!$C$25,0)) -> 0 | M19: =SUM(IF(10=MAX(1,ROUNDUP(Assumptions!$C$9/30,0)),C12*Assumptions!$C$25,0),IF(9=MAX(1,ROUNDUP(Assumptions!$C$9/30,0)),D12*Assumptions!$C$25,0),IF(8=MAX(1,ROUNDUP(Assumptions!$C$9/30,0)),E12*Assumptions!$C$25,0),IF(7=MAX(1,ROUNDUP(Assumptions!$C$9/30,0)),F12*Assumptions!$C$25,0),IF(6=MAX(1,ROUNDUP(Assumptions!$C$9/30,0)),G12*Assumptions!$C$25,0),IF(5=MAX(1,ROUNDUP(Assumptions!$C$9/30,0)),H12*Assumptions!$C$25,0),IF(4=MAX(1,ROUNDUP(Assumptions!$C$9/30,0)),I12*Assumptions!$C$25,0),IF(3=MAX(1,ROUNDUP(Assumptions!$C$9/30,0)),J12*Assumptions!$C$25,0),IF(2=MAX(1,ROUNDUP(Assumptions!$C$9/30,0)),K12*Assumptions!$C$25,0),IF(1=MAX(1,ROUNDUP(Assumptions!$C$9/30,0)),L12*Assumptions!$C$25,0),IF(0=MAX(1,ROUNDUP(Assumptions!$C$9/30,0)),M12*Assumptions!$C$25,0)) -> 0 | N19: =SUM(IF(11=MAX(1,ROUNDUP(Assumptions!$C$9/30,0)),C12*Assumptions!$C$25,0),IF(10=MAX(1,ROUNDUP(Assumptions!$C$9/30,0)),D12*Assumptions!$C$25,0),IF(9=MAX(1,ROUNDUP(Assumptions!$C$9/30,0)),E12*Assumptions!$C$25,0),IF(8=MAX(1,ROUNDUP(Assumptions!$C$9/30,0)),F12*Assumptions!$C$25,0),IF(7=MAX(1,ROUNDUP(Assumptions!$C$9/30,0)),G12*Assumptions!$C$25,0),IF(6=MAX(1,ROUNDUP(Assumptions!$C$9/30,0)),H12*Assumptions!$C$25,0),IF(5=MAX(1,ROUNDUP(Assumptions!$C$9/30,0)),I12*Assumptions!$C$25,0),IF(4=MAX(1,ROUNDUP(Assumptions!$C$9/30,0)),J12*Assumptions!$C$25,0),IF(3=MAX(1,ROUNDUP(Assumptions!$C$9/30,0)),K12*Assumptions!$C$25,0),IF(2=MAX(1,ROUNDUP(Assumptions!$C$9/30,0)),L12*Assumptions!$C$25,0),IF(1=MAX(1,ROUNDUP(Assumptions!$C$9/30,0)),M12*Assumptions!$C$25,0),IF(0=MAX(1,ROUNDUP(Assumptions!$C$9/30,0)),N12*Assumptions!$C$25,0)) -> 0 | O19: =SUM(IF(12=MAX(1,ROUNDUP(Assumptions!$C$9/30,0)),C12*Assumptions!$C$25,0),IF(11=MAX(1,ROUNDUP(Assumptions!$C$9/30,0)),D12*Assumptions!$C$25,0),IF(10=MAX(1,ROUNDUP(Assumptions!$C$9/30,0)),E12*Assumptions!$C$25,0),IF(9=MAX(1,ROUNDUP(Assumptions!$C$9/30,0)),F12*Assumptions!$C$25,0),IF(8=MAX(1,ROUNDUP(Assumptions!$C$9/30,0)),G12*Assumptions!$C$25,0),IF(7=MAX(1,ROUNDUP(Assumptions!$C$9/30,0)),H12*Assumptions!$C$25,0),IF(6=MAX(1,ROUNDUP(Assumptions!$C$9/30,0)),I12*Assumptions!$C$25,0),IF(5=MAX(1,ROUNDUP(Assumptions!$C$9/30,0)),J12*Assumptions!$C$25,0),IF(4=MAX(1,ROUNDUP(Assumptions!$C$9/30,0)),K12*Assumptions!$C$25,0),IF(3=MAX(1,ROUNDUP(Assumptions!$C$9/30,0)),L12*Assumptions!$C$25,0),IF(2=MAX(1,ROUNDUP(Assumptions!$C$9/30,0)),M12*Assumptions!$C$25,0),IF(1=MAX(1,ROUNDUP(Assumptions!$C$9/30,0)),N12*Assumptions!$C$25,0),IF(0=MAX(1,ROUNDUP(Assumptions!$C$9/30,0)),O12*Assumptions!$C$25,0)) -> 0 | P19: =SUM(IF(13=MAX(1,ROUNDUP(Assumptions!$C$9/30,0)),C12*Assumptions!$C$25,0),IF(12=MAX(1,ROUNDUP(Assumptions!$C$9/30,0)),D12*Assumptions!$C$25,0),IF(11=MAX(1,ROUNDUP(Assumptions!$C$9/30,0)),E12*Assumptions!$C$25,0),IF(10=MAX(1,ROUNDUP(Assumptions!$C$9/30,0)),F12*Assumptions!$C$25,0),IF(9=MAX(1,ROUNDUP(Assumptions!$C$9/30,0)),G12*Assumptions!$C$25,0),IF(8=MAX(1,ROUNDUP(Assumptions!$C$9/30,0)),H12*Assumptions!$C$25,0),IF(7=MAX(1,ROUNDUP(Assumptions!$C$9/30,0)),I12*Assumptions!$C$25,0),IF(6=MAX(1,ROUNDUP(Assumptions!$C$9/30,0)),J12*Assumptions!$C$25,0),IF(5=MAX(1,ROUNDUP(Assumptions!$C$9/30,0)),K12*Assumptions!$C$25,0),IF(4=MAX(1,ROUNDUP(Assumptions!$C$9/30,0)),L12*Assumptions!$C$25,0),IF(3=MAX(1,ROUNDUP(Assumptions!$C$9/30,0)),M12*Assumptions!$C$25,0),IF(2=MAX(1,ROUNDUP(Assumptions!$C$9/30,0)),N12*Assumptions!$C$25,0),IF(1=MAX(1,ROUNDUP(Assumptions!$C$9/30,0)),O12*Assumptions!$C$25,0),IF(0=MAX(1,ROUNDUP(Assumptions!$C$9/30,0)),P12*Assumptions!$C$25,0)) -> 0 | Q19: =SUM(IF(14=MAX(1,ROUNDUP(Assumptions!$C$9/30,0)),C12*Assumptions!$C$25,0),IF(13=MAX(1,ROUNDUP(Assumptions!$C$9/30,0)),D12*Assumptions!$C$25,0),IF(12=MAX(1,ROUNDUP(Assumptions!$C$9/30,0)),E12*Assumptions!$C$25,0),IF(11=MAX(1,ROUNDUP(Assumptions!$C$9/30,0)),F12*Assumptions!$C$25,0),IF(10=MAX(1,ROUNDUP(Assumptions!$C$9/30,0)),G12*Assumptions!$C$25,0),IF(9=MAX(1,ROUNDUP(Assumptions!$C$9/30,0)),H12*Assumptions!$C$25,0),IF(8=MAX(1,ROUNDUP(Assumptions!$C$9/30,0)),I12*Assumptions!$C$25,0),IF(7=MAX(1,ROUNDUP(Assumptions!$C$9/30,0)),J12*Assumptions!$C$25,0),IF(6=MAX(1,ROUNDUP(Assumptions!$C$9/30,0)),K12*Assumptions!$C$25,0),IF(5=MAX(1,ROUNDUP(Assumptions!$C$9/30,0)),L12*Assumptions!$C$25,0),IF(4=MAX(1,ROUNDUP(Assumptions!$C$9/30,0)),M12*Assumptions!$C$25,0),IF(3=MAX(1,ROUNDUP(Assumptions!$C$9/30,0)),N12*Assumptions!$C$25,0),IF(2=MAX(1,ROUNDUP(Assumptions!$C$9/30,0)),O12*Assumptions!$C$25,0),IF(1=MAX(1,ROUNDUP(Assumptions!$C$9/30,0)),P12*Assumptions!$C$25,0),IF(0=MAX(1,ROUNDUP(Assumptions!$C$9/30,0)),Q12*Assumptions!$C$25,0)) -> 0 | R19: =SUM(IF(15=MAX(1,ROUNDUP(Assumptions!$C$9/30,0)),C12*Assumptions!$C$25,0),IF(14=MAX(1,ROUNDUP(Assumptions!$C$9/30,0)),D12*Assumptions!$C$25,0),IF(13=MAX(1,ROUNDUP(Assumptions!$C$9/30,0)),E12*Assumptions!$C$25,0),IF(12=MAX(1,ROUNDUP(Assumptions!$C$9/30,0)),F12*Assumptions!$C$25,0),IF(11=MAX(1,ROUNDUP(Assumptions!$C$9/30,0)),G12*Assumptions!$C$25,0),IF(10=MAX(1,ROUNDUP(Assumptions!$C$9/30,0)),H12*Assumptions!$C$25,0),IF(9=MAX(1,ROUNDUP(Assumptions!$C$9/30,0)),I12*Assumptions!$C$25,0),IF(8=MAX(1,ROUNDUP(Assumptions!$C$9/30,0)),J12*Assumptions!$C$25,0),IF(7=MAX(1,ROUNDUP(Assumptions!$C$9/30,0)),K12*Assumptions!$C$25,0),IF(6=MAX(1,ROUNDUP(Assumptions!$C$9/30,0)),L12*Assumptions!$C$25,0),IF(5=MAX(1,ROUNDUP(Assumptions!$C$9/30,0)),M12*Assumptions!$C$25,0),IF(4=MAX(1,ROUNDUP(Assumptions!$C$9/30,0)),N12*Assumptions!$C$25,0),IF(3=MAX(1,ROUNDUP(Assumptions!$C$9/30,0)),O12*Assumptions!$C$25,0),IF(2=MAX(1,ROUNDUP(Assumptions!$C$9/30,0)),P12*Assumptions!$C$25,0),IF(1=MAX(1,ROUNDUP(Assumptions!$C$9/30,0)),Q12*Assumptions!$C$25,0),IF(0=MAX(1,ROUNDUP(Assumptions!$C$9/30,0)),R12*Assumptions!$C$25,0)) -> 0 | S19: =SUM(IF(16=MAX(1,ROUNDUP(Assumptions!$C$9/30,0)),C12*Assumptions!$C$25,0),IF(15=MAX(1,ROUNDUP(Assumptions!$C$9/30,0)),D12*Assumptions!$C$25,0),IF(14=MAX(1,ROUNDUP(Assumptions!$C$9/30,0)),E12*Assumptions!$C$25,0),IF(13=MAX(1,ROUNDUP(Assumptions!$C$9/30,0)),F12*Assumptions!$C$25,0),IF(12=MAX(1,ROUNDUP(Assumptions!$C$9/30,0)),G12*Assumptions!$C$25,0),IF(11=MAX(1,ROUNDUP(Assumptions!$C$9/30,0)),H12*Assumptions!$C$25,0),IF(10=MAX(1,ROUNDUP(Assumptions!$C$9/30,0)),I12*Assumptions!$C$25,0),IF(9=MAX(1,ROUNDUP(Assumptions!$C$9/30,0)),J12*Assumptions!$C$25,0),IF(8=MAX(1,ROUNDUP(Assumptions!$C$9/30,0)),K12*Assumptions!$C$25,0),IF(7=MAX(1,ROUNDUP(Assumptions!$C$9/30,0)),L12*Assumptions!$C$25,0),IF(6=MAX(1,ROUNDUP(Assumptions!$C$9/30,0)),M12*Assumptions!$C$25,0),IF(5=MAX(1,ROUNDUP(Assumptions!$C$9/30,0)),N12*Assumptions!$C$25,0),IF(4=MAX(1,ROUNDUP(Assumptions!$C$9/30,0)),O12*Assumptions!$C$25,0),IF(3=MAX(1,ROUNDUP(Assumptions!$C$9/30,0)),P12*Assumptions!$C$25,0),IF(2=MAX(1,ROUNDUP(Assumptions!$C$9/30,0)),Q12*Assumptions!$C$25,0),IF(1=MAX(1,ROUNDUP(Assumptions!$C$9/30,0)),R12*Assumptions!$C$25,0),IF(0=MAX(1,ROUNDUP(Assumptions!$C$9/30,0)),S12*Assumptions!$C$25,0)) -> 0 | T19: =SUM(IF(17=MAX(1,ROUNDUP(Assumptions!$C$9/30,0)),C12*Assumptions!$C$25,0),IF(16=MAX(1,ROUNDUP(Assumptions!$C$9/30,0)),D12*Assumptions!$C$25,0),IF(15=MAX(1,ROUNDUP(Assumptions!$C$9/30,0)),E12*Assumptions!$C$25,0),IF(14=MAX(1,ROUNDUP(Assumptions!$C$9/30,0)),F12*Assumptions!$C$25,0),IF(13=MAX(1,ROUNDUP(Assumptions!$C$9/30,0)),G12*Assumptions!$C$25,0),IF(12=MAX(1,ROUNDUP(Assumptions!$C$9/30,0)),H12*Assumptions!$C$25,0),IF(11=MAX(1,ROUNDUP(Assumptions!$C$9/30,0)),I12*Assumptions!$C$25,0),IF(10=MAX(1,ROUNDUP(Assumptions!$C$9/30,0)),J12*Assumptions!$C$25,0),IF(9=MAX(1,ROUNDUP(Assumptions!$C$9/30,0)),K12*Assumptions!$C$25,0),IF(8=MAX(1,ROUNDUP(Assumptions!$C$9/30,0)),L12*Assumptions!$C$25,0),IF(7=MAX(1,ROUNDUP(Assumptions!$C$9/30,0)),M12*Assumptions!$C$25,0),IF(6=MAX(1,ROUNDUP(Assumptions!$C$9/30,0)),N12*Assumptions!$C$25,0),IF(5=MAX(1,ROUNDUP(Assumptions!$C$9/30,0)),O12*Assumptions!$C$25,0),IF(4=MAX(1,ROUNDUP(Assumptions!$C$9/30,0)),P12*Assumptions!$C$25,0),IF(3=MAX(1,ROUNDUP(Assumptions!$C$9/30,0)),Q12*Assumptions!$C$25,0),IF(2=MAX(1,ROUNDUP(Assumptions!$C$9/30,0)),R12*Assumptions!$C$25,0),IF(1=MAX(1,ROUNDUP(Assumptions!$C$9/30,0)),S12*Assumptions!$C$25,0),IF(0=MAX(1,ROUNDUP(Assumptions!$C$9/30,0)),T12*Assumptions!$C$25,0)) -> 0 | U19: =SUM(IF(18=MAX(1,ROUNDUP(Assumptions!$C$9/30,0)),C12*Assumptions!$C$25,0),IF(17=MAX(1,ROUNDUP(Assumptions!$C$9/30,0)),D12*Assumptions!$C$25,0),IF(16=MAX(1,ROUNDUP(Assumptions!$C$9/30,0)),E12*Assumptions!$C$25,0),IF(15=MAX(1,ROUNDUP(Assumptions!$C$9/30,0)),F12*Assumptions!$C$25,0),IF(14=MAX(1,ROUNDUP(Assumptions!$C$9/30,0)),G12*Assumptions!$C$25,0),IF(13=MAX(1,ROUNDUP(Assumptions!$C$9/30,0)),H12*Assumptions!$C$25,0),IF(12=MAX(1,ROUNDUP(Assumptions!$C$9/30,0)),I12*Assumptions!$C$25,0),IF(11=MAX(1,ROUNDUP(Assumptions!$C$9/30,0)),J12*Assumptions!$C$25,0),IF(10=MAX(1,ROUNDUP(Assumptions!$C$9/30,0)),K12*Assumptions!$C$25,0),IF(9=MAX(1,ROUNDUP(Assumptions!$C$9/30,0)),L12*Assumptions!$C$25,0),IF(8=MAX(1,ROUNDUP(Assumptions!$C$9/30,0)),M12*Assumptions!$C$25,0),IF(7=MAX(1,ROUNDUP(Assumptions!$C$9/30,0)),N12*Assumptions!$C$25,0),IF(6=MAX(1,ROUNDUP(Assumptions!$C$9/30,0)),O12*Assumptions!$C$25,0),IF(5=MAX(1,ROUNDUP(Assumptions!$C$9/30,0)),P12*Assumptions!$C$25,0),IF(4=MAX(1,ROUNDUP(Assumptions!$C$9/30,0)),Q12*Assumptions!$C$25,0),IF(3=MAX(1,ROUNDUP(Assumptions!$C$9/30,0)),R12*Assumptions!$C$25,0),IF(2=MAX(1,ROUNDUP(Assumptions!$C$9/30,0)),S12*Assumptions!$C$25,0),IF(1=MAX(1,ROUNDUP(Assumptions!$C$9/30,0)),T12*Assumptions!$C$25,0),IF(0=MAX(1,ROUNDUP(Assumptions!$C$9/30,0)),U12*Assumptions!$C$25,0)) -> 0 | V19: =SUM(IF(19=MAX(1,ROUNDUP(Assumptions!$C$9/30,0)),C12*Assumptions!$C$25,0),IF(18=MAX(1,ROUNDUP(Assumptions!$C$9/30,0)),D12*Assumptions!$C$25,0),IF(17=MAX(1,ROUNDUP(Assumptions!$C$9/30,0)),E12*Assumptions!$C$25,0),IF(16=MAX(1,ROUNDUP(Assumptions!$C$9/30,0)),F12*Assumptions!$C$25,0),IF(15=MAX(1,ROUNDUP(Assumptions!$C$9/30,0)),G12*Assumptions!$C$25,0),IF(14=MAX(1,ROUNDUP(Assumptions!$C$9/30,0)),H12*Assumptions!$C$25,0),IF(13=MAX(1,ROUNDUP(Assumptions!$C$9/30,0)),I12*Assumptions!$C$25,0),IF(12=MAX(1,ROUNDUP(Assumptions!$C$9/30,0)),J12*Assumptions!$C$25,0),IF(11=MAX(1,ROUNDUP(Assumptions!$C$9/30,0)),K12*Assumptions!$C$25,0),IF(10=MAX(1,ROUNDUP(Assumptions!$C$9/30,0)),L12*Assumptions!$C$25,0),IF(9=MAX(1,ROUNDUP(Assumptions!$C$9/30,0)),M12*Assumptions!$C$25,0),IF(8=MAX(1,ROUNDUP(Assumptions!$C$9/30,0)),N12*Assumptions!$C$25,0),IF(7=MAX(1,ROUNDUP(Assumptions!$C$9/30,0)),O12*Assumptions!$C$25,0),IF(6=MAX(1,ROUNDUP(Assumptions!$C$9/30,0)),P12*Assumptions!$C$25,0),IF(5=MAX(1,ROUNDUP(Assumptions!$C$9/30,0)),Q12*Assumptions!$C$25,0),IF(4=MAX(1,ROUNDUP(Assumptions!$C$9/30,0)),R12*Assumptions!$C$25,0),IF(3=MAX(1,ROUNDUP(Assumptions!$C$9/30,0)),S12*Assumptions!$C$25,0),IF(2=MAX(1,ROUNDUP(Assumptions!$C$9/30,0)),T12*Assumptions!$C$25,0),IF(1=MAX(1,ROUNDUP(Assumptions!$C$9/30,0)),U12*Assumptions!$C$25,0),IF(0=MAX(1,ROUNDUP(Assumptions!$C$9/30,0)),V12*Assumptions!$C$25,0)) -> 0 | W19: =SUM(IF(20=MAX(1,ROUNDUP(Assumptions!$C$9/30,0)),C12*Assumptions!$C$25,0),IF(19=MAX(1,ROUNDUP(Assumptions!$C$9/30,0)),D12*Assumptions!$C$25,0),IF(18=MAX(1,ROUNDUP(Assumptions!$C$9/30,0)),E12*Assumptions!$C$25,0),IF(17=MAX(1,ROUNDUP(Assumptions!$C$9/30,0)),F12*Assumptions!$C$25,0),IF(16=MAX(1,ROUNDUP(Assumptions!$C$9/30,0)),G12*Assumptions!$C$25,0),IF(15=MAX(1,ROUNDUP(Assumptions!$C$9/30,0)),H12*Assumptions!$C$25,0),IF(14=MAX(1,ROUNDUP(Assumptions!$C$9/30,0)),I12*Assumptions!$C$25,0),IF(13=MAX(1,ROUNDUP(Assumptions!$C$9/30,0)),J12*Assumptions!$C$25,0),IF(12=MAX(1,ROUNDUP(Assumptions!$C$9/30,0)),K12*Assumptions!$C$25,0),IF(11=MAX(1,ROUNDUP(Assumptions!$C$9/30,0)),L12*Assumptions!$C$25,0),IF(10=MAX(1,ROUNDUP(Assumptions!$C$9/30,0)),M12*Assumptions!$C$25,0),IF(9=MAX(1,ROUNDUP(Assumptions!$C$9/30,0)),N12*Assumptions!$C$25,0),IF(8=MAX(1,ROUNDUP(Assumptions!$C$9/30,0)),O12*Assumptions!$C$25,0),IF(7=MAX(1,ROUNDUP(Assumptions!$C$9/30,0)),P12*Assumptions!$C$25,0),IF(6=MAX(1,ROUNDUP(Assumptions!$C$9/30,0)),Q12*Assumptions!$C$25,0),IF(5=MAX(1,ROUNDUP(Assumptions!$C$9/30,0)),R12*Assumptions!$C$25,0),IF(4=MAX(1,ROUNDUP(Assumptions!$C$9/30,0)),S12*Assumptions!$C$25,0),IF(3=MAX(1,ROUNDUP(Assumptions!$C$9/30,0)),T12*Assumptions!$C$25,0),IF(2=MAX(1,ROUNDUP(Assumptions!$C$9/30,0)),U12*Assumptions!$C$25,0),IF(1=MAX(1,ROUNDUP(Assumptions!$C$9/30,0)),V12*Assumptions!$C$25,0),IF(0=MAX(1,ROUNDUP(Assumptions!$C$9/30,0)),W12*Assumptions!$C$25,0)) -> 0 | X19: =SUM(IF(21=MAX(1,ROUNDUP(Assumptions!$C$9/30,0)),C12*Assumptions!$C$25,0),IF(20=MAX(1,ROUNDUP(Assumptions!$C$9/30,0)),D12*Assumptions!$C$25,0),IF(19=MAX(1,ROUNDUP(Assumptions!$C$9/30,0)),E12*Assumptions!$C$25,0),IF(18=MAX(1,ROUNDUP(Assumptions!$C$9/30,0)),F12*Assumptions!$C$25,0),IF(17=MAX(1,ROUNDUP(Assumptions!$C$9/30,0)),G12*Assumptions!$C$25,0),IF(16=MAX(1,ROUNDUP(Assumptions!$C$9/30,0)),H12*Assumptions!$C$25,0),IF(15=MAX(1,ROUNDUP(Assumptions!$C$9/30,0)),I12*Assumptions!$C$25,0),IF(14=MAX(1,ROUNDUP(Assumptions!$C$9/30,0)),J12*Assumptions!$C$25,0),IF(13=MAX(1,ROUNDUP(Assumptions!$C$9/30,0)),K12*Assumptions!$C$25,0),IF(12=MAX(1,ROUNDUP(Assumptions!$C$9/30,0)),L12*Assumptions!$C$25,0),IF(11=MAX(1,ROUNDUP(Assumptions!$C$9/30,0)),M12*Assumptions!$C$25,0),IF(10=MAX(1,ROUNDUP(Assumptions!$C$9/30,0)),N12*Assumptions!$C$25,0),IF(9=MAX(1,ROUNDUP(Assumptions!$C$9/30,0)),O12*Assumptions!$C$25,0),IF(8=MAX(1,ROUNDUP(Assumptions!$C$9/30,0)),P12*Assumptions!$C$25,0),IF(7=MAX(1,ROUNDUP(Assumptions!$C$9/30,0)),Q12*Assumptions!$C$25,0),IF(6=MAX(1,ROUNDUP(Assumptions!$C$9/30,0)),R12*Assumptions!$C$25,0),IF(5=MAX(1,ROUNDUP(Assumptions!$C$9/30,0)),S12*Assumptions!$C$25,0),IF(4=MAX(1,ROUNDUP(Assumptions!$C$9/30,0)),T12*Assumptions!$C$25,0),IF(3=MAX(1,ROUNDUP(Assumptions!$C$9/30,0)),U12*Assumptions!$C$25,0),IF(2=MAX(1,ROUNDUP(Assumptions!$C$9/30,0)),V12*Assumptions!$C$25,0),IF(1=MAX(1,ROUNDUP(Assumptions!$C$9/30,0)),W12*Assumptions!$C$25,0),IF(0=MAX(1,ROUNDUP(Assumptions!$C$9/30,0)),X12*Assumptions!$C$25,0)) -> 0 | Y19: =SUM(IF(22=MAX(1,ROUNDUP(Assumptions!$C$9/30,0)),C12*Assumptions!$C$25,0),IF(21=MAX(1,ROUNDUP(Assumptions!$C$9/30,0)),D12*Assumptions!$C$25,0),IF(20=MAX(1,ROUNDUP(Assumptions!$C$9/30,0)),E12*Assumptions!$C$25,0),IF(19=MAX(1,ROUNDUP(Assumptions!$C$9/30,0)),F12*Assumptions!$C$25,0),IF(18=MAX(1,ROUNDUP(Assumptions!$C$9/30,0)),G12*Assumptions!$C$25,0),IF(17=MAX(1,ROUNDUP(Assumptions!$C$9/30,0)),H12*Assumptions!$C$25,0),IF(16=MAX(1,ROUNDUP(Assumptions!$C$9/30,0)),I12*Assumptions!$C$25,0),IF(15=MAX(1,ROUNDUP(Assumptions!$C$9/30,0)),J12*Assumptions!$C$25,0),IF(14=MAX(1,ROUNDUP(Assumptions!$C$9/30,0)),K12*Assumptions!$C$25,0),IF(13=MAX(1,ROUNDUP(Assumptions!$C$9/30,0)),L12*Assumptions!$C$25,0),IF(12=MAX(1,ROUNDUP(Assumptions!$C$9/30,0)),M12*Assumptions!$C$25,0),IF(11=MAX(1,ROUNDUP(Assumptions!$C$9/30,0)),N12*Assumptions!$C$25,0),IF(10=MAX(1,ROUNDUP(Assumptions!$C$9/30,0)),O12*Assumptions!$C$25,0),IF(9=MAX(1,ROUNDUP(Assumptions!$C$9/30,0)),P12*Assumptions!$C$25,0),IF(8=MAX(1,ROUNDUP(Assumptions!$C$9/30,0)),Q12*Assumptions!$C$25,0),IF(7=MAX(1,ROUNDUP(Assumptions!$C$9/30,0)),R12*Assumptions!$C$25,0),IF(6=MAX(1,ROUNDUP(Assumptions!$C$9/30,0)),S12*Assumptions!$C$25,0),IF(5=MAX(1,ROUNDUP(Assumptions!$C$9/30,0)),T12*Assumptions!$C$25,0),IF(4=MAX(1,ROUNDUP(Assumptions!$C$9/30,0)),U12*Assumptions!$C$25,0),IF(3=MAX(1,ROUNDUP(Assumptions!$C$9/30,0)),V12*Assumptions!$C$25,0),IF(2=MAX(1,ROUNDUP(Assumptions!$C$9/30,0)),W12*Assumptions!$C$25,0),IF(1=MAX(1,ROUNDUP(Assumptions!$C$9/30,0)),X12*Assumptions!$C$25,0),IF(0=MAX(1,ROUNDUP(Assumptions!$C$9/30,0)),Y12*Assumptions!$C$25,0)) -> 0 | Z19: =SUM(IF(23=MAX(1,ROUNDUP(Assumptions!$C$9/30,0)),C12*Assumptions!$C$25,0),IF(22=MAX(1,ROUNDUP(Assumptions!$C$9/30,0)),D12*Assumptions!$C$25,0),IF(21=MAX(1,ROUNDUP(Assumptions!$C$9/30,0)),E12*Assumptions!$C$25,0),IF(20=MAX(1,ROUNDUP(Assumptions!$C$9/30,0)),F12*Assumptions!$C$25,0),IF(19=MAX(1,ROUNDUP(Assumptions!$C$9/30,0)),G12*Assumptions!$C$25,0),IF(18=MAX(1,ROUNDUP(Assumptions!$C$9/30,0)),H12*Assumptions!$C$25,0),IF(17=MAX(1,ROUNDUP(Assumptions!$C$9/30,0)),I12*Assumptions!$C$25,0),IF(16=MAX(1,ROUNDUP(Assumptions!$C$9/30,0)),J12*Assumptions!$C$25,0),IF(15=MAX(1,ROUNDUP(Assumptions!$C$9/30,0)),K12*Assumptions!$C$25,0),IF(14=MAX(1,ROUNDUP(Assumptions!$C$9/30,0)),L12*Assumptions!$C$25,0),IF(13=MAX(1,ROUNDUP(Assumptions!$C$9/30,0)),M12*Assumptions!$C$25,0),IF(12=MAX(1,ROUNDUP(Assumptions!$C$9/30,0)),N12*Assumptions!$C$25,0),IF(11=MAX(1,ROUNDUP(Assumptions!$C$9/30,0)),O12*Assumptions!$C$25,0),IF(10=MAX(1,ROUNDUP(Assumptions!$C$9/30,0)),P12*Assumptions!$C$25,0),IF(9=MAX(1,ROUNDUP(Assumptions!$C$9/30,0)),Q12*Assumptions!$C$25,0),IF(8=MAX(1,ROUNDUP(Assumptions!$C$9/30,0)),R12*Assumptions!$C$25,0),IF(7=MAX(1,ROUNDUP(Assumptions!$C$9/30,0)),S12*Assumptions!$C$25,0),IF(6=MAX(1,ROUNDUP(Assumptions!$C$9/30,0)),T12*Assumptions!$C$25,0),IF(5=MAX(1,ROUNDUP(Assumptions!$C$9/30,0)),U12*Assumptions!$C$25,0),IF(4=MAX(1,ROUNDUP(Assumptions!$C$9/30,0)),V12*Assumptions!$C$25,0),IF(3=MAX(1,ROUNDUP(Assumptions!$C$9/30,0)),W12*Assumptions!$C$25,0),IF(2=MAX(1,ROUNDUP(Assumptions!$C$9/30,0)),X12*Assumptions!$C$25,0),IF(1=MAX(1,ROUNDUP(Assumptions!$C$9/30,0)),Y12*Assumptions!$C$25,0),IF(0=MAX(1,ROUNDUP(Assumptions!$C$9/30,0)),Z12*Assumptions!$C$25,0)) -> 0
A20: 사전예약 무료월 후 유료 | B20: 명 | C20: =IF(0=Assumptions!$C$12,$C$8*Assumptions!$C$26,0) -> 0 | D20: =IF(1=Assumptions!$C$12,$C$8*Assumptions!$C$26,0) -> 4.2 | E20: =IF(2=Assumptions!$C$12,$C$8*Assumptions!$C$26,0) -> 0 | F20: =IF(3=Assumptions!$C$12,$C$8*Assumptions!$C$26,0) -> 0 | G20: =IF(4=Assumptions!$C$12,$C$8*Assumptions!$C$26,0) -> 0 | H20: =IF(5=Assumptions!$C$12,$C$8*Assumptions!$C$26,0) -> 0 | I20: =IF(6=Assumptions!$C$12,$C$8*Assumptions!$C$26,0) -> 0 | J20: =IF(7=Assumptions!$C$12,$C$8*Assumptions!$C$26,0) -> 0 | K20: =IF(8=Assumptions!$C$12,$C$8*Assumptions!$C$26,0) -> 0 | L20: =IF(9=Assumptions!$C$12,$C$8*Assumptions!$C$26,0) -> 0 | M20: =IF(10=Assumptions!$C$12,$C$8*Assumptions!$C$26,0) -> 0 | N20: =IF(11=Assumptions!$C$12,$C$8*Assumptions!$C$26,0) -> 0 | O20: =IF(12=Assumptions!$C$12,$C$8*Assumptions!$C$26,0) -> 0 | P20: =IF(13=Assumptions!$C$12,$C$8*Assumptions!$C$26,0) -> 0 | Q20: =IF(14=Assumptions!$C$12,$C$8*Assumptions!$C$26,0) -> 0 | R20: =IF(15=Assumptions!$C$12,$C$8*Assumptions!$C$26,0) -> 0 | S20: =IF(16=Assumptions!$C$12,$C$8*Assumptions!$C$26,0) -> 0 | T20: =IF(17=Assumptions!$C$12,$C$8*Assumptions!$C$26,0) -> 0 | U20: =IF(18=Assumptions!$C$12,$C$8*Assumptions!$C$26,0) -> 0 | V20: =IF(19=Assumptions!$C$12,$C$8*Assumptions!$C$26,0) -> 0 | W20: =IF(20=Assumptions!$C$12,$C$8*Assumptions!$C$26,0) -> 0 | X20: =IF(21=Assumptions!$C$12,$C$8*Assumptions!$C$26,0) -> 0 | Y20: =IF(22=Assumptions!$C$12,$C$8*Assumptions!$C$26,0) -> 0 | Z20: =IF(23=Assumptions!$C$12,$C$8*Assumptions!$C$26,0) -> 0
A21: 전체 신규 유료 | B21: 명 | C21: =SUM(C18:C20) -> 3 | D21: =SUM(D18:D20) -> 7.5705 | E21: =SUM(E18:E20) -> 3.326022 | F21: =SUM(F18:F20) -> 3.472875 | G21: =SUM(G18:G20) -> 3.6465187 | H21: =SUM(H18:H20) -> 3.8288447 | I21: =SUM(I18:I20) -> 4.0202869 | J21: =SUM(J18:J20) -> 4.2213013 | ... Z21: =SUM(Z18:Z20) -> 9.2145713
A22: Essential 기초 유료 | B22: 명 | C22: =0 -> 0 | D22: =C31 -> 1.2 | E22: =D31 -> 4.1514 | F22: =E31 -> 5.2161192 | G22: =F31 -> 6.2714376 | H22: =G31 -> 7.3286731 | I22: =H31 -> 8.3911759 | J22: =I31 -> 9.4622554 | K22: =J31 -> 10.545192 | ... Z22: =Y31 -> 30.475253
A23: 학생가 기초 유료 | B23: 명 | C23: =0 -> 0 | D23: =C32 -> 1.35 | E23: =D32 -> 4.670325 | F23: =E32 -> 5.8681341 | G23: =F32 -> 7.0553673 | H23: =G32 -> 8.2447572 | I23: =H32 -> 9.4400728 | J23: =I32 -> 10.645037 | K23: =J32 -> 11.86334 | ... Z23: =Y32 -> 34.284659
A24: Pro 기초 유료 | B24: 명 | C24: =0 -> 0 | D24: =C33 -> 0.45 | E24: =D33 -> 1.556775 | F24: =E33 -> 1.9560447 | G24: =F33 -> 2.3517891 | H24: =G33 -> 2.7482524 | I24: =H33 -> 3.1466909 | J24: =I33 -> 3.5483458 | K24: =J33 -> 3.9544468 | ... Z24: =Y33 -> 11.42822
A25: Essential 이탈 | B25: 명 | C25: =C22*Assumptions!$C$28 -> 0 | D25: =D22*Assumptions!$C$28 -> 0.0768 | E25: =E22*Assumptions!$C$28 -> 0.2656896 | F25: =F22*Assumptions!$C$28 -> 0.33383163 | G25: =G22*Assumptions!$C$28 -> 0.401372 | H25: =H22*Assumptions!$C$28 -> 0.46903508 | I25: =I22*Assumptions!$C$28 -> 0.53703526 | J25: =J22*Assumptions!$C$28 -> 0.60558434 | ... Z25: =Z22*Assumptions!$C$28 -> 1.9504162
A26: 학생가 이탈 | B26: 명 | C26: =C23*Assumptions!$C$29 -> 0 | D26: =D23*Assumptions!$C$29 -> 0.0864 | E26: =E23*Assumptions!$C$29 -> 0.2989008 | F26: =F23*Assumptions!$C$29 -> 0.37556058 | G26: =G23*Assumptions!$C$29 -> 0.45154351 | H26: =H23*Assumptions!$C$29 -> 0.52766446 | I26: =I23*Assumptions!$C$29 -> 0.60416466 | J26: =J23*Assumptions!$C$29 -> 0.68128239 | ... Z26: =Z23*Assumptions!$C$29 -> 2.1942182
A27: Pro 이탈 | B27: 명 | C27: =C24*Assumptions!$C$30 -> 0 | D27: =D24*Assumptions!$C$30 -> 0.0288 | E27: =E24*Assumptions!$C$30 -> 0.0996336 | F27: =F24*Assumptions!$C$30 -> 0.12518686 | G27: =G24*Assumptions!$C$30 -> 0.1505145 | H27: =H24*Assumptions!$C$30 -> 0.17588815 | I27: =I24*Assumptions!$C$30 -> 0.20138822 | J27: =J24*Assumptions!$C$30 -> 0.22709413 | ... Z27: =Z24*Assumptions!$C$30 -> 0.73140606
A28: Essential 신규 유료 | B28: 명 | C28: =C21*Assumptions!$C$33 -> 1.2 | D28: =D21*Assumptions!$C$33 -> 3.0282 | E28: =E21*Assumptions!$C$33 -> 1.3304088 | F28: =F21*Assumptions!$C$33 -> 1.38915 | G28: =G21*Assumptions!$C$33 -> 1.4586075 | H28: =H21*Assumptions!$C$33 -> 1.5315379 | I28: =I21*Assumptions!$C$33 -> 1.6081148 | J28: =J21*Assumptions!$C$33 -> 1.6885205 | ... Z28: =Z21*Assumptions!$C$33 -> 3.6858285
A29: 학생가 신규 유료 | B29: 명 | C29: =C21*Assumptions!$C$34 -> 1.35 | D29: =D21*Assumptions!$C$34 -> 3.406725 | E29: =E21*Assumptions!$C$34 -> 1.4967099 | F29: =F21*Assumptions!$C$34 -> 1.5627938 | G29: =G21*Assumptions!$C$34 -> 1.6409334 | H29: =H21*Assumptions!$C$34 -> 1.7229801 | I29: =I21*Assumptions!$C$34 -> 1.8091291 | J29: =J21*Assumptions!$C$34 -> 1.8995856 | ... Z29: =Z21*Assumptions!$C$34 -> 4.1465571
A30: Pro 신규 유료 | B30: 명 | C30: =C21*Assumptions!$C$35 -> 0.45 | D30: =D21*Assumptions!$C$35 -> 1.135575 | E30: =E21*Assumptions!$C$35 -> 0.4989033 | F30: =F21*Assumptions!$C$35 -> 0.52093125 | G30: =G21*Assumptions!$C$35 -> 0.54697781 | H30: =H21*Assumptions!$C$35 -> 0.5743267 | I30: =I21*Assumptions!$C$35 -> 0.60304304 | J30: =J21*Assumptions!$C$35 -> 0.63319519 | ... Z30: =Z21*Assumptions!$C$35 -> 1.3821857
A31: Essential 기말 유료 | B31: 명 | C31: =C22-C25+C28 -> 1.2 | D31: =D22-D25+D28 -> 4.1514 | E31: =E22-E25+E28 -> 5.2161192 | F31: =F22-F25+F28 -> 6.2714376 | G31: =G22-G25+G28 -> 7.3286731 | H31: =H22-H25+H28 -> 8.3911759 | I31: =I22-I25+I28 -> 9.4622554 | J31: =J22-J25+J28 -> 10.545192 | ... Z31: =Z22-Z25+Z28 -> 32.210665
A32: 학생가 기말 유료 | B32: 명 | C32: =C23-C26+C29 -> 1.35 | D32: =D23-D26+D29 -> 4.670325 | E32: =E23-E26+E29 -> 5.8681341 | F32: =F23-F26+F29 -> 7.0553673 | G32: =G23-G26+G29 -> 8.2447572 | H32: =H23-H26+H29 -> 9.4400728 | I32: =I23-I26+I29 -> 10.645037 | J32: =J23-J26+J29 -> 11.86334 | ... Z32: =Z23-Z26+Z29 -> 36.236998
A33: Pro 기말 유료 | B33: 명 | C33: =C24-C27+C30 -> 0.45 | D33: =D24-D27+D30 -> 1.556775 | E33: =E24-E27+E30 -> 1.9560447 | F33: =F24-F27+F30 -> 2.3517891 | G33: =G24-G27+G30 -> 2.7482524 | H33: =H24-H27+H30 -> 3.1466909 | I33: =I24-I27+I30 -> 3.5483458 | J33: =J24-J27+J30 -> 3.9544468 | ... Z33: =Z24-Z27+Z30 -> 12.078999
A34: 전체 기말 유료 | B34: 명 | C34: =SUM(C31:C33) -> 3 | D34: =SUM(D31:D33) -> 10.3785 | E34: =SUM(E31:E33) -> 13.040298 | F34: =SUM(F31:F33) -> 15.678594 | G34: =SUM(G31:G33) -> 18.321683 | H34: =SUM(H31:H33) -> 20.97794 | I34: =SUM(I31:I33) -> 23.655638 | J34: =SUM(J31:J33) -> 26.362979 | ... Z34: =SUM(Z31:Z33) -> 80.526663
A35: Free 기초 활성 | B35: 명 | C35: =0 -> 0 | D35: =C40 -> 21.878 | E35: =D40 -> 40.215452 | F35: =E40 -> 47.14815 | G35: =F40 -> 52.933703 | H35: =G40 -> 58.018228 | I35: =H40 -> 62.661322 | J35: =I40 -> 67.047328 | K35: =J40 -> 71.308025 | ... Z35: =Y40 -> 153.23732
A36: 신규 Free (유료·체험 제외) | B36: 명 | C36: =C14-C15 -> 21.878 | D36: =D14-D15 -> 17.881752 | E36: =E14-E15 -> 18.7425 | F36: =F14-F15 -> 19.679625 | G36: =G14-G15 -> 20.663606 | H36: =H14-H15 -> 21.696787 | I36: =I14-I15 -> 22.781626 | J36: =J14-J15 -> 23.920707 | ... Z36: =Z14-Z15 -> 52.215904
